Workbook
Name _: #REF!
Name _: #REF!
Name _: #REF!
Name _: #REF!
Name _: #REF!
Name _: #REF!
Name _: #REF!
Name ___UFP123: #REF!
Name ___UFP123: #REF!
Name ___UFP123: #REF!
Name ___UFP123: #REF!
Name ___UFP123: #REF!
Name ___UFP123: #REF!
Name __DAT2: #REF!
Name __DAT2: #REF!
Name __DAT2: #REF!
Name __DAT2: #REF!
Name __DAT2: #REF!
Name __DAT3: #REF!
Name __DAT3: #REF!
Name __DAT3: #REF!
Name __DAT3: #REF!
Name __DAT3: #REF!
Name __DAT4: #REF!
Name __DAT4: #REF!
Name __DAT4: #REF!
Name __DAT4: #REF!
Name __DAT4: #REF!
Name __DAT5: #REF!
Name __DAT5: #REF!
Name __DAT5: #REF!
Name __DAT5: #REF!
Name __DAT5: #REF!
Name __DAT6: #REF!
Name __DAT6: #REF!
Name __DAT6: #REF!
Name __DAT6: #REF!
Name __DAT6: #REF!
Name __DAT7: #REF!
Name __DAT7: #REF!
Name __DAT7: #REF!
Name __DAT7: #REF!
Name __DAT7: #REF!
Name __DAT8: #REF!
Name __DAT8: #REF!
Name __DAT8: #REF!
Name __DAT8: #REF!
Name __DAT8: #REF!
Name __DAT9: #REF!
Name __DAT9: #REF!
Name __DAT9: #REF!
Name __DAT9: #REF!
Name __DAT9: #REF!
Name __UFP123: #REF!
Name __UFP123: #REF!
Name __UFP123: #REF!
Name __UFP123: #REF!
Name __UFP123: #REF!
Name _007: #REF!
Name _007: #REF!

Sheet 营销BI分析体系
A2: 管理分析体系 | B2: 一期-★★★ | C2: 一期-★★★ | D2: 二期 | E2: 二期 | F2: 二期 | G2: 一期-★★ | H2: 一期-★★★ | I2: 二期 | J2: 一期-★★ | K2: 一期-★★
A4: 核心价值 | B4: 一保一拓三提升
B5: 营销
B6: 营收保障 | C6: 业务拓展 | D6: 运营效率提升 | H6: 客户提升 | J6: 组织能力提升
B7: 扩大营业收入 | C7: 强化业务拓展跟进 | D7: 扩大品牌认知 | E7: 提升市场运作效率 | F7: 严控费用 | G7: 提升运营效率 | H7: 提升经销商能力及效率 | I7: 优化客户结构？ | J7: 提升营销人效 | K7: 增强团队能力建设
A9: 分析主题域
B10: 收入分析 | C10: 业务拓展分析 | D10: 品牌分析 | E10: 市场分析 | F10: 费用分析 | G10: 运营效率分析 | H10: 经销商分析 | I10: 客户分析？ | J10: 人效分析 | K10: 团队能力分析
A12: 分析主题 | I12: 客户分层（A+ABC)，分行业，分产出
B13: 营业收入分析 | C13: 签约分析 | D13: 品牌指数分析 | E13: 二级覆盖度 | F13: 招待费分析 | G13: 销售预测准确率分析 | H13: 渠道结构分析 | I13: 客户结构分析？ | J13: 人员效率分析 | K13: 职级分析
B14: 销量分析 | C14: 商机分析 | D14: 专项曝光分析 | E14: 活动成效分析 | F14: 差旅费分析 | G14: 物流效率分析 | H14: 二级分析 | I14: 客户复购率分析？
B15: 配比分析 | C15: 样机分析 | D15: 用户案例分析 | F15: 广宣费分析 | G15: 分仓效率分析 | H15: 返利分析 | I15: 客户流失分析？(FML）
B16: 价格分析 | C16: 接单分析 | F16: 运输费分析 | G16: 库存周转分析 | H16: 库存分析 | I16: 定制项目投入产出分析？
B17: 订单分析 | C17: 线索分析 | F17: 服务费分析 | H17: 赋能分析 | I17: 客户成单周期分析？
I18: 订单分析？价格？
A21: 指标体系
A23: 核心指标(高层) | B23: 总裁/副总裁
A24: 每个主题<=3 | B24: 市场份额 | C24: 签约达成率 | D24: 品牌指数排名 | E24: 二级覆盖率 | F24: 费率 | G24: 销售预测准确率 | H24: 渠道结构、分销比 | I24: 客户结构 | J24: 营销人均收入 | K24: BG总人数
B25: 收入达成率、同比增长率 | C25: 商机达成率、转化率 | E25: 市场活动投入产出比 | F25: 费用同比增长率 | G25: 库存周转天数、超期库存占比 | H25: 二级承载率、有效率、单商产能 | J25: 营销人均利润 | K25: 营销人数，占比
B26: 毛利率 | C26: 接单达成 | G26: 交付周期 | H26: 核心库存周转天数
A28: 一级指标(中层) | B28: 部门/BU负责人
B29: 营业收入 | C29: 签约达成率 | D29: 品牌指数排名 | E29: 二级覆盖率 | F29: 费率、达成率、同比 | G29: 销售预测准确率 | H29: 渠道结构、分销比 | I29: 客户结构 | J29: 营销人均收入 | K29: 营销人数
B30: 收入达成率及排名、同比 | C30: 商机达成率、转化率、缺口 | D30: 专项曝光度 | E30: 市场活动投入产出比 | F30: 招待费占比、达成率、同比 | G30: 物流时效 | H30: 二级承载率、有效率、单商产能 | I30: 客户复购率 | J30: 营销人均利润 | K30: 营销人数占比
B31: 整机销量 | C31: 接单达成 | D31: 用户案例证言数量 | E31: 留资成本 | F31: 差旅费占比、达成率、同比 | G31: 分仓出货占比 | H31: 返利余额、可使用月份数 | I31: 客户流失率 | J31: 营销人均人力成本 | K31: 营销人数同比增长率
B32: 整机销量同比 | C32: 线索有效率 | F32: 广宣费占比、达成率、同比 | G32: 库存量 | H32: 核心库存量 | I32: 定制项目投入产出比 | J32: 营销人均招待费 | K32: 职级人数占比
B33: 周边配比 | C33: 线索及时率 | F33: 运输费占比、达成率、同比 | G33: 交付周期 | H33: 核心库存周转天数 | I33: 客户成单周期 | J33: 营销人均差旅费
B34: 低价占比 | C34: 样机申请率 | F34: 服务费占比、达成率、同比 | G34: 库存周转天数 | H34: 赋能覆盖率 | I34: 订单均价
B35: 订单平均金额 | C35: 样机在外量 | F35: 整机平均运输费
C36: 样机转销率 | F36: 整机平均安装费
C37: 样机逾期率
A41: 二级指标(执行层) | B41: 各区域省份负责人等
B42: 营业收入 | C42: 签约达成率、缺口 | D42: 品牌指数排名 | E42: 二级覆盖率 | F42: 费率、达成率、同比 | G42: 销售预测准确率 | H42: 渠道结构、分销比 | I42: 客户结构 | J42: 营销人均收入 | K42: 营销人数
B43: 收入达成率及排名、同比 | C43: 商机达成率、转化率、缺口 | D43: 专项曝光度 | E43: 市场活动数量 | F43: 招待费占比、达成率、同比 | G43: 物流时效 | H43: 二级承载率、有效率、单商产能 | I43: 客户复购率 | J43: 营销人均利润 | K43: 营销人数占比
B44: 整机销量 | C44: 接单达成 | D44: 用户案例证言数量 | E44: 市场活动投入产出比 | F44: 差旅费占比、达成率、同比 | G44: 分仓出货占比 | H44: 返利余额、可使用月份数 | I44: 客户流失率 | J44: 营销人均人力成本 | K44: 营销人数同比增长率
B45: 整机销量同比 | C45: 线索有效率 | E45: 留资成本 | F45: 广宣费占比、达成率、同比 | G45: 库存量 | H45: 核心库存量 | I45: 定制项目投入产出比 | J45: 营销人均招待费 | K45: 职级人数占比
B46: 低价占比 | C46: 样机在外量 | F46: 运输费占比、达成率、同比 | G46: 交付周期 | H46: 核心库存周转天数 | I46: 客户成单周期 | J46: 营销人均差旅费
B47: 订单平均金额 | C47: 样机转销率 | F47: 服务费占比、达成率、同比 | G47: 库存周转天数 | H47: 赋能覆盖率 | I47: 订单均价
C48: 样机逾期率 | F48: 整机平均运输费
F49: 整机平均安装费
A52: 维度
A53: 管理维度 | B53: 高层 | C53: 中层 | D53: 执行层： | E53: 品牌 | F53: 市场 | G53: 渠管 | H53: 商务 | I53: 计划 | J53: 物流 | K53: 客服等
...

Sheet 教育BI规划
A1: 分析内容 | E1: 主要分析维度 | O1: 频度 | P1: 紧急度 | Q1: 管理层级 | R1: 其他备注 | AA1: 日 | AB1: 周 | AC1: 月 | AD1: 季 | AE1: 半年 | AF1: 年
A2: 营销端价值链 | B2: 模块 | C2: 主题 | D2: 指标 | E2: 期间 | F2: 事业部 | G2: 项目 | H2: 产品线 | I2: 产品型号 | J2: 系列 | K2: 尺寸 | L2: 区域 | M2: 客户 | N2: 办事处 | AA2: BG | AB2: BU/一级部门 | AC2: 部门内 | AD2: 区域 | AE2: 办事处
B3: 商业计划 | C3: 产品规划 | D3: 产品企划命中率 | E3: √ | F3: √ | G3: √ | I3: √ | O3: 月 | P3: 一般 | Q3: BG | R3: 已立项可集成 | AA3: 紧急 | AB3: 一般 | AC3: 可延后
D4: 关键里程碑达成率 | E4: √ | F4: √ | G4: √ | I4: √ | J4: √ | K4: √ | O4: 周 | P4: 一般 | Q4: BG | R4: 集成已有BI
D5: 量产后销售进度达成率 | E5: √ | F5: √ | G5: √ | I5: √ | O5: 月 | P5: 一般 | Q5: BG | R5: 已立项可集成
C6: 销售目标 | D6: 预算达成 | E6: √ | F6: √ | H6: √ | J6: √ | K6: √ | L6: √ | N6: √ | O6: 月 | P6: 紧急 | Q6: BG
D7: 结构达成 | E7: √ | F7: √ | H7: √ | I7: √ | J7: √ | K7: √ | L7: √ | N7: √ | O7: 月 | P7: 紧急 | Q7: BG
D8: 预测达成 | E8: √ | F8: √ | L8: √ | O8: 周 | P8: 紧急 | Q8: BG
B9: 商机管理 | C9: 商机项目管理 | D9: 商机项目数量/金额（分阶段） | E9: √ | F9: √ | G9: √ | H9: √ | I9: √ | L9: √ | M9: √ | O9: 周 | P9: 紧急 | Q9: BG
D10: 商机转化率 | E10: √ | F10: √ | G10: √ | I10: √ | L10: √ | N10: √ | O10: 月 | P10: 紧急 | Q10: BG
D11: 线索中标量/金额 | E11: √ | F11: √ | G11: √ | I11: √ | L11: √ | N11: √ | O11: 日 | P11: 紧急 | Q11: BG
D12: 订单转化率金额 | E12: √ | F12: √ | G12: √ | I12: √ | L12: √ | N12: √ | O12: 日 | P12: 紧急 | Q12: BG
D13: 收入转化率/金额 | E13: √ | F13: √ | G13: √ | I13: √ | L13: √ | N13: √ | O13: 日 | P13: 紧急 | Q13: BG
D14: 中标转化订单周期 | E14: √ | F14: √ | G14: √ | L14: √ | M14: √ | N14: √ | O14: 周 | P14: 紧急 | Q14: BG
D15: 订单转化收入周期 | E15: √ | F15: √ | G15: √ | L15: √ | M15: √ | N15: √ | O15: 周 | P15: 紧急 | Q15: BG
C16: 订单管理 | D16: 订单数量/金额/单平均 | E16: √ | F16: √ | H16: √ | I16: √ | J16: √ | K16: √ | L16: √ | M16: √ | O16: 日 | P16: 紧急 | Q16: BG
D17: 订单未出货 | E17: √ | F17: √ | H17: √ | I17: √ | J17: √ | K17: √ | L17: √ | M17: √ | O17: 周 | P17: 紧急 | Q17: BG
D18: 合同配置效率 | E18: √ | F18: √ | H18: √ | I18: √ | J18: √ | K18: √ | L18: √ | M18: √ | O18: 月 | P18: 一般 | Q18: BU/一级部门
B19: 客户管理 | C19: 大客户销售管理 | D19: 客户份额占比 | E19: √ | F19: √ | H19: √ | I19: √ | J19: √ | K19: √ | L19: √ | M19: √ | N19: 延后 | O19: 月 | P19: 可延后 | Q19: BG
D20: 客户业绩贡献率 | E20: √ | F20: √ | H20: √ | I20: √ | J20: √ | K20: √ | L20: √ | M20: √ | N20: 延后 | O20: 月 | P20: 可延后 | Q20: BG
C21: 渠道管理 | D21: 渠道数量（新增及活跃数） | E21: √ | F21: √ | L21: √ | O21: 月 | P21: 紧急 | Q21: BG | R21: 已有BI优化
D22: 渠道业绩贡献（甄别有效渠道） | E22: √ | F22: √ | L22: √ | O22: 月 | P22: 紧急 | Q22: BG
D23: 电商平台 | E23: √ | F23: √ | L23: √ | N23: 延后 | O23: 日 | P23: 可延后 | Q23: BG
B24: 销售运营 | C24: 人均效率 | D24: 人均营收 | E24: √ | F24: √ | L24: √ | N24: √ | O24: 周 | P24: 紧急 | Q24: BG
D25: 人均净利 | E25: √ | F25: √ | L25: √ | N25: √ | O25: 月 | P25: 紧急 | Q25: BG
D26: 人均接单额 | E26: √ | F26: √ | L26: √ | N26: √ | O26: 周 | P26: 紧急 | Q26: BG
C27: 费用管理 | D27: 人力成本 | E27: √ | F27: √ | L27: √ | N27: √ | O27: 月 | P27: 紧急 | Q27: BG
D28: 差旅费投入产出 | E28: √ | F28: √ | G28: √ | L28: √ | M28: √ | N28: √ | O28: 月 | P28: 紧急 | Q28: BG
D29: 招待费投入产出 | E29: √ | F29: √ | G29: √ | L29: √ | M29: √ | N29: √ | O29: 月 | P29: 紧急 | Q29: BG
D30: 广宣费投入产出 | E30: √ | F30: √ | G30: √ | L30: √ | M30: √ | N30: √ | O30: 周 | P30: 紧急 | Q30: BG
D31: 物流运输费用 | E31: √ | F31: √ | I31: √ | J31: √ | K31: √ | O31: 月 | P31: 紧急 | Q31: BG
C32: 销售政策管理 | D32: 销售政策执行情况 | E32: √ | F32: √ | H32: √ | I32: √ | J32: √ | K32: √ | L32: √ | M32: √ | N32: √ | O32: 月 | P32: 紧急 | Q32: BG
D33: 政策性资源返利管理 | E33: √ | F33: √ | G33: √ | N33: √ | O33: 月 | P33: 紧急 | Q33: BG
B34: 盈利能力 | C34: 价格管理 | D34: 低于底价出货 | E34: √ | F34: √ | G34: √ | H34: √ | I34: √ | J34: √ | K34: √ | L34: √ | M34: √ | N34: √ | O34: 月 | P34: 紧急 | Q34: BG | R34: 已有BI优化
D35: 单价趋势（系列、机型） | E35: √ | F35: √ | H35: √ | I35: √ | J35: √ | K35: √ | L35: √ | M35: √ | N35: √ | O35: 月 | P35: 紧急 | Q35: BG
C36: 产品盈利能力 | D36: 收入 | E36: √ | F36: √ | H36: √ | I36: √ | J36: √ | K36: √ | L36: √ | M36: √ | N36: √ | O36: 日 | P36: 紧急 | Q36: BG
D37: 毛利额/毛利率 | E37: √ | F37: √ | H37: √ | I37: √ | J37: √ | K37: √ | L37: √ | M37: √ | N37: √ | O37: 月 | P37: 紧急 | Q37: BG
B38: 库存管理 | C38: 样机管理 | D38: 样机结存数量/金额 | E38: √ | F38: √ | H38: √ | I38: √ | J38: √ | K38: √ | L38: √ | N38: √ | O38: 月 | P38: 一般 | Q38: BG | R38: 已有BI优化
D39: 样机分用途及超期预警 | E39: √ | F39: √ | H39: √ | I39: √ | J39: √ | K39: √ | L39: √ | N39: √ | O39: 月 | P39: 紧急 | Q39: BG
D40: 样机盘点及管理报表 | E40: √ | F40: √ | H40: √ | I40: √ | J40: √ | K40: √ | L40: √ | N40: √ | O40: 月 | P40: 紧急 | Q40: BG
...

Sheet 指标体系-企服
B1: 一期 | C1: 部门价值填在此列 | AE1: 若无参考方法论可不填写
A2: 指标领域 | B2: 核心价值 | C2: 关键驱动因素 | D2: 分析主题域 | E2: 分析主题 | F2: 指标等级 | G2: 指标名称 | H2: 定义 | I2: 公式 | J2: 计算口径 | K2: 维度 | W2: 度量单位 | X2: 统计频率 | Y2: 统计精度 | Z2: 数据来源 | AA2: 优先级 | AB2: 指标用途 | AC2: 考核角色 | AD2: 要求角色 | AE2: 对应SCOR模型
K3: 期间 | L3: 事业部 | M3: 项目 | N3: 产品线 | O3: 产品型号 | P3: 系列 | Q3: 尺寸 | R3: 区域 | S3: 客户 | T3: 办事处 | U3: 仓位 | V3: 人员 | AF3: 对接人 | AG3: 是否相同 | AH3: 是否重复 | AI3: 核心价值
B4: 1.营收保障 | AE4: Reliability(可靠性)
A5: 营销 | B5: 扩大营业收入 | D5: 收入分析 | E5: 营业收入分析 | F5: 核心指标 | G5: 收入达成率 | H5: 完成收入目标的比例 | I5: 营业收入/收入目标 | J5: 1.BG 2.营业收入即不含税销售额 | K5: √ | L5: √ | N5: √ | O5: √ | P5: √ | Q5: √ | R5: √ | S5: √ | T5: √ | V5: √ | W5: % | X5: 日/周/月/季/年 | Y5: 两位小数点 | Z5: EBS/导入 | AA5: ★★★ | AB5: 内部管理 | AD5: 总裁/副总裁 | AF5: 潘敏君 | AG5: =VLOOKUP(G5,'指标体系-教育'!G:G,1,0)=G5 -> TRUE | AI5: 营收保障
A6: 营销 | B6: 扩大营业收入 | D6: 收入分析 | E6: 营业收入分析 | F6: 核心指标 | G6: 收入同比增长率 | H6: 收入同比增长比例 | I6: 本期营业收入/同期营业收入 | J6: BG | W6: % | X6: 月/季/年 | Y6: 两位小数点 | Z6: EBS | AA6: ★★★ | AB6: 内部管理 | AD6: 总裁/副总裁 | AF6: 潘敏君 | AG6: =VLOOKUP(G6,'指标体系-教育'!G:G,1,0)=G6 -> TRUE | AI6: =AI5 -> 营收保障
A7: 营销 | B7: 扩大营业收入 | D7: 收入分析 | E7: 营业收入分析 | F7: 核心指标 | G7: 毛利率 | H7: 毛利额占收入比例 | I7: 毛利额/营业收入 | J7: BG | K7: √ | L7: √ | N7: √ | O7: √ | P7: √ | Q7: √ | R7: √ | S7: √ | T7: √ | V7: √ | W7: % | X7: 月/季/年 | Y7: 两位小数点 | Z7: EBS | AA7: ★★★ | AB7: 内部管理 | AD7: 总裁/副总裁 | AF7: 潘敏君 | AG7: =VLOOKUP(G7,'指标体系-教育'!G:G,1,0)=G7 -> TRUE | AH7: 否 | AI7: =AI6 -> 营收保障
A8: 营销 | B8: 扩大营业收入 | D8: 收入分析 | E8: 营业收入分析 | F8: 一级指标 | G8: 营业收入 | H8: 营业收入 | I8: 营业收入 | J8: BG、分BU | K8: √ | L8: √ | N8: √ | O8: √ | P8: √ | Q8: √ | R8: √ | S8: √ | T8: √ | V8: √ | W8: 万元 | X8: 日/周/月/季/年 | Y8: 无小数点 | Z8: EBS | AA8: ★★★ | AB8: 内部管理 | AD8: 部门/BU负责人 | AF8: 潘敏君 | AG8: =VLOOKUP(G8,'指标体系-教育'!G:G,1,0)=G8 -> TRUE | AH8: 否 | AI8: =AI7 -> 营收保障
A9: 营销 | B9: 扩大营业收入 | D9: 收入分析 | E9: 营业收入分析 | F9: 一级指标 | G9: 收入达成率及排名 | H9: 完成收入目标的比例 | I9: 营业收入/收入目标 | J9: BG、分BU | W9: % | X9: 日/周/月/季/年 | Y9: 两位小数点 | Z9: EBS/导入 | AA9: ★★★ | AB9: 内部管理 | AD9: 部门/BU负责人 | AF9: 潘敏君 | AG9: =VLOOKUP(G9,'指标体系-教育'!G:G,1,0)=G9 -> TRUE | AH9: 否 | AI9: =AI8 -> 营收保障
A10: 营销 | B10: 扩大营业收入 | D10: 收入分析 | E10: 营业收入分析 | F10: 一级指标 | G10: 收入同比增长率 | H10: 收入同比增长比例 | I10: 本期营业收入/同期营业收入 | J10: BG、分BU | W10: % | X10: 月/季/年 | Y10: 两位小数点 | Z10: EBS | AA10: ★★★ | AB10: 内部管理 | AD10: 部门/BU负责人 | AF10: 潘敏君 | AG10: =VLOOKUP(G10,'指标体系-教育'!G:G,1,0)=G10 -> TRUE | AH10: 否 | AI10: =AI9 -> 营收保障
A11: 营销 | B11: 扩大营业收入 | D11: 收入分析 | E11: 销量分析 | F11: 一级指标 | G11: 整机销量 | H11: 整机销量 | I11: 整机销量 | J11: BG、分BU | K11: √ | L11: √ | N11: √ | O11: √ | P11: √ | Q11: √ | R11: √ | S11: √ | T11: √ | V11: √ | W11: 台 | X11: 日/周/月/季/年 | Y11: 无小数点 | Z11: EBS | AA11: ★★★ | AB11: 内部管理 | AD11: 部门/BU负责人 | AF11: 潘敏君 | AG11: =VLOOKUP(G11,'指标体系-教育'!G:G,1,0)=G11 -> TRUE | AH11: 否 | AI11: =AI10 -> 营收保障
A12: 营销 | B12: 扩大营业收入 | D12: 收入分析 | E12: 销量分析 | F12: 一级指标 | G12: 整机销量同比增长率 | H12: 整机销量同比增长比例 | I12: 本期整机销量/同期整机销量 | J12: BG、分BU | W12: % | X12: 月/季/年 | Y12: 两位小数点 | Z12: EBS | AA12: ★★★ | AB12: 内部管理 | AD12: 部门/BU负责人 | AF12: 潘敏君 | AG12: =VLOOKUP(G12,'指标体系-教育'!G:G,1,0)=G12 -> TRUE | AH12: 否 | AI12: =AI11 -> 营收保障
A13: 营销 | B13: 扩大营业收入 | D13: 收入分析 | E13: 配比分析 | F13: 一级指标 | G13: 周边配比 | H13: 周边收入占整体(整机+周边)收入比例 | I13: 周边营业收入/整体营业收入 | J13: BG、分BU | K13: √ | L13: √ | N13: √ | O13: √ | P13: √ | W13: % | X13: 月/季/年 | Y13: 两位小数点 | Z13: EBS | AA13: ★★ | AB13: 内部管理 | AD13: 部门/BU负责人 | AF13: 龚芬芬 | AG13: =VLOOKUP(G13,'指标体系-教育'!G:G,1,0)=G13 -> TRUE | AH13: 否 | AI13: =AI12 -> 营收保障
A14: 营销 | B14: 扩大营业收入 | D14: 收入分析 | E14: 配比分析 | F14: 一级指标 | G14: 主要周边销量配比 | H14: XX销量占对应整机销量比例 | I14: XX销量/对应整机销量 | J14: BG、分BU | K14: √ | L14: √ | N14: √ | O14: √ | P14: √ | W14: % | X14: 月/季/年 | Y14: 两位小数点 | Z14: EBS | AA14: ★★ | AB14: 内部管理 | AD14: 部门/BU负责人 | AF14: 龚芬芬 | AG14: =VLOOKUP(G14,'指标体系-教育'!G:G,1,0)=G14 -> TRUE | AH14: 否 | AI14: =AI13 -> 营收保障
A15: 营销 | B15: 扩大营业收入 | D15: 收入分析 | E15: 价格分析 | F15: 一级指标 | G15: 低价量占比 | H15: 低价单销量占整机销量比例 | I15: 低价单整机销量/整机销量 | J15: 1.BG、分BU 2.低价：低于核心价 | K15: √ | L15: √ | R15: √ | S15: √ | T15: √ | V15: √ | W15: % | X15: 月/季/年 | Y15: 两位小数点 | Z15: SCRM/EBS | AA15: ★★ | AB15: 内部管理 | AD15: 部门/BU负责人 | AF15: 龚芬芬 | AG15: =VLOOKUP(G15,'指标体系-教育'!G:G,1,0)=G15 -> TRUE | AH15: 否 | AI15: =AI14 -> 营收保障
A16: 营销 | B16: 扩大营业收入 | D16: 收入分析 | E16: 订单分析 | F16: 一级指标 | G16: 订单平均金额 | H16: 平均每个订单含税销售额 | I16: 含税销售额/订单数量 | J16: 1.BG、分BU 2.销售额即IN-销售额，含税 | K16: √ | L16: √ | R16: √ | S16: √ | T16: √ | V16: √ | W16: 万元 | X16: 日/周/月/季/年 | Y16: 无小数点 | Z16: EBS | AA16: ★★ | AB16: 内部管理 | AD16: 部门/BU负责人 | AF16: 龚芬芬 | AG16: =VLOOKUP(G16,'指标体系-教育'!G:G,1,0)=G16 -> TRUE | AH16: 否 | AI16: =AI15 -> 营收保障
A17: 营销 | B17: 扩大营业收入 | D17: 收入分析 | E17: 营业收入分析 | F17: 二级指标 | G17: 营业收入 | H17: 营业收入 | I17: 营业收入 | J17: BG、分BU、分区域、分办事处、分人员 | K17: √ | L17: √ | N17: √ | O17: √ | P17: √ | Q17: √ | R17: √ | S17: √ | T17: √ | V17: √ | W17: 万元 | X17: 日/周/月/季/年 | Y17: 无小数点 | Z17: EBS | AA17: ★★★ | AB17: 内部管理 | AD17: 区域/办事处负责人 | AF17: 潘敏君 | AG17: =VLOOKUP(G17,'指标体系-教育'!G:G,1,0)=G17 -> TRUE | AI17: =AI16 -> 营收保障
A18: 营销 | B18: 扩大营业收入 | D18: 收入分析 | E18: 营业收入分析 | F18: 二级指标 | G18: 收入达成率及排名 | H18: 完成收入目标的比例 | I18: 营业收入/收入目标 | J18: BG、分BU、分区域、分办事处、分人员 | W18: % | X18: 日/周/月/季/年 | Y18: 两位小数点 | Z18: EBS/导入 | AA18: ★★★ | AB18: 内部管理 | AD18: 区域/办事处负责人 | AF18: 潘敏君 | AG18: =VLOOKUP(G18,'指标体系-教育'!G:G,1,0)=G18 -> TRUE | AI18: =AI17 -> 营收保障
A19: 营销 | B19: 扩大营业收入 | D19: 收入分析 | E19: 营业收入分析 | F19: 二级指标 | G19: 收入同比增长率 | H19: 收入同比增长比例 | I19: 本期营业收入/同期营业收入 | J19: BG、分BU、分区域、分办事处、分人员 | W19: % | X19: 月/季/年 | Y19: 两位小数点 | Z19: EBS | AA19: ★★★ | AB19: 内部管理 | AD19: 区域/办事处负责人 | AF19: 潘敏君 | AG19: =VLOOKUP(G19,'指标体系-教育'!G:G,1,0)=G19 -> TRUE | AI19: =AI18 -> 营收保障
A20: 营销 | B20: 扩大营业收入 | D20: 收入分析 | E20: 销量分析 | F20: 二级指标 | G20: 整机销量 | H20: 整机销量 | I20: 整机销量 | J20: BG、分BU、分区域、分办事处、分人员 | K20: √ | L20: √ | N20: √ | O20: √ | P20: √ | Q20: √ | R20: √ | S20: √ | T20: √ | V20: √ | W20: 台 | X20: 日/周/月/季/年 | Y20: 无小数点 | Z20: EBS | AA20: ★★★ | AB20: 内部管理 | AD20: 区域/办事处负责人 | AF20: 潘敏君 | AG20: =VLOOKUP(G20,'指标体系-教育'!G:G,1,0)=G20 -> TRUE | AI20: =AI19 -> 营收保障
A21: 营销 | B21: 扩大营业收入 | D21: 收入分析 | E21: 销量分析 | F21: 二级指标 | G21: 整机销量同比增长率 | H21: 整机销量同比增长比例 | I21: 本期整机销量/同期整机销量 | J21: BG、分BU、分区域、分办事处、分人员 | W21: % | X21: 月/季/年 | Y21: 两位小数点 | Z21: EBS | AA21: ★★★ | AB21: 内部管理 | AD21: 区域/办事处负责人 | AF21: 潘敏君 | AG21: =VLOOKUP(G21,'指标体系-教育'!G:G,1,0)=G21 -> TRUE | AI21: =AI20 -> 营收保障
A22: 营销 | B22: 扩大营业收入 | D22: 收入分析 | E22: 价格分析 | F22: 二级指标 | G22: 低价量占比 | H22: 低价单销量占整机销量比例 | I22: 低价单整机销量/整机销量 | J22: 1.BG、分BU、分区域、分办事处、分人员 2.低价：低于核心价 | K22: √ | L22: √ | R22: √ | S22: √ | T22: √ | V22: √ | W22: % | X22: 月/季/年 | Y22: 两位小数点 | Z22: EBS/门户系统 | AA22: ★★ | AB22: 内部管理 | AD22: 区域/办事处负责人 | AF22: 龚芬芬 | AG22: =VLOOKUP(G22,'指标体系-教育'!G:G,1,0)=G22 -> TRUE | AI22: =AI21 -> 营收保障
A23: 营销 | B23: 扩大营业收入 | D23: 收入分析 | E23: 订单分析 | F23: 二级指标 | G23: 订单平均金额 | H23: 平均每个订单含税销售额 | I23: 含税销售额/订单数量 | J23: 1.BG、分BU、分区域、分办事处、分人员 2.销售额即IN-销售额，含税 | K23: √ | L23: √ | R23: √ | S23: √ | T23: √ | V23: √ | W23: 万元 | X23: 日/周/月/季/年 | Y23: 无小数点 | Z23: EBS | AA23: ★★ | AB23: 内部管理 | AD23: 区域/办事处负责人 | AF23: 龚芬芬 | AG23: =VLOOKUP(G23,'指标体系-教育'!G:G,1,0)=G23 -> TRUE | AI23: =AI22 -> 营收保障
B24: 2.业务拓展
A25: 营销 | B25: 强化业务拓展跟进 | D25: 业务拓展分析 | E25: 签约分析 | F25: 核心指标 | G25: 签约达成率 | H25: 完成签约数量目标的比例 | I25: 签约数量/签约数量目标 | J25: 渠道平台 | K25: √ | L25: √ | R25: √ | S25: √ | T25: √ | V25: √ | W25: % | X25: 日/周/月/季/年 | Y25: 两位小数点 | Z25: SCRM/导入 | AA25: ★★★ | AB25: 内部管理 | AD25: 总裁/副总裁 | AF25: 龚芬芬 | AG25: =VLOOKUP(G25,'指标体系-教育'!G:G,1,0)=G25 -> TRUE | AI25: 业务拓展
A26: 营销 | B26: 强化业务拓展跟进 | D26: 业务拓展分析 | E26: 商机分析 | F26: 核心指标 | G26: 商机达成率 | H26: 完成商机目标的比例 | I26: 商机额/商机目标 | J26: 1.渠道平台 2.商机额=商机量*核心价，含税 | K26: √ | L26: √ | N26: √ | O26: √ | P26: √ | Q26: √ | R26: √ | S26: √ | T26: √ | V26: √ | W26: % | X26: 日/周/月/季/年 | Y26: 两位小数点 | Z26: SCRM/导入 | AA26: ★★★ | AB26: 内部管理 | AD26: 总裁/副总裁 | AF26: 龚芬芬 | AG26: 否 | AI26: =AI25 -> 业务拓展
A27: 营销 | B27: 强化业务拓展跟进 | D27: 业务拓展分析 | E27: 商机分析 | F27: 核心指标 | G27: 商机转化率 | H27: 商机转化为销售的比例 | I27: 销售额/商机额 | J27: 1.渠道平台 2.商机额销售额均含税 | K27: √ | L27: √ | N27: √ | O27: √ | P27: √ | Q27: √ | R27: √ | S27: √ | T27: √ | V27: √ | W27: % | X27: 日/周/月/季/年 | Y27: 两位小数点 | Z27: SCRM/CRM | AA27: ★★★ | AB27: 内部管理 | AD27: 总裁/副总裁 | AF27: 龚芬芬 | AG27: =VLOOKUP(G27,'指标体系-教育'!G:G,1,0)=G27 -> TRUE | AI27: =AI26 -> 业务拓展
A28: 营销 | B28: 强化业务拓展跟进 | D28: 业务拓展分析 | E28: 接单分析 | F28: 核心指标 | G28: 接单达成率 | H28: 完成接单目标的比例 | I28: 接单量/接单目标 | J28: BG | K28: √ | L28: √ | R28: √ | S28: √ | T28: √ | V28: √ | W28: % | X28: 日/周/月/季/年 | Y28: 两位小数点 | Z28: SCRM/CRM | AA28: ★★★ | AB28: 内部管理 | AD28: 总裁/副总裁 | AF28: 龚芬芬 | AG28: 否 | AI28: =AI27 -> 业务拓展
A29: 营销 | B29: 强化业务拓展跟进 | D29: 业务拓展分析 | E29: 签约分析 | F29: 一级指标 | G29: 签约达成率 | H29: 完成签约数量目标的比例 | I29: 签约数量/签约数量目标 | J29: 渠道平台 | K29: √ | L29: √ | R29: √ | S29: √ | T29: √ | V29: √ | W29: % | X29: 日/周/月/季/年 | Y29: 两位小数点 | Z29: SCRM/导入 | AA29: ★★★ | AB29: 内部管理 | AD29: 部门/BU负责人 | AF29: 龚芬芬 | AG29: =VLOOKUP(G29,'指标体系-教育'!G:G,1,0)=G29 -> TRUE | AH29: 否 | AI29: =AI28 -> 业务拓展
A30: 营销 | B30: 强化业务拓展跟进 | D30: 业务拓展分析 | E30: 商机分析 | F30: 一级指标 | G30: 商机达成率 | H30: 完成商机目标的比例 | I30: 商机额/商机目标 | J30: 1.渠道平台 2.商机额=商机量*核心价，含税 | K30: √ | L30: √ | N30: √ | O30: √ | P30: √ | Q30: √ | R30: √ | S30: √ | T30: √ | V30: √ | W30: % | X30: 日/周/月/季/年 | Y30: 两位小数点 | Z30: SCRM/导入 | AA30: ★★★ | AB30: 内部管理 | AD30: 部门/BU负责人 | AF30: 龚芬芬 | AG30: 否 | AH30: 否 | AI30: =AI29 -> 业务拓展
A31: 营销 | B31: 强化业务拓展跟进 | D31: 业务拓展分析 | E31: 商机分析 | F31: 一级指标 | G31: 商机转化率 | H31: 商机转化为销售的比例 | I31: 销售额/商机额 | J31: 1.渠道平台 2.商机额销售额均含税 | K31: √ | L31: √ | N31: √ | O31: √ | P31: √ | Q31: √ | R31: √ | S31: √ | T31: √ | V31: √ | W31: % | X31: 日/周/月/季/年 | Y31: 两位小数点 | Z31: SCRM/CRM | AA31: ★★★ | AB31: 内部管理 | AD31: 部门/BU负责人 | AF31: 龚芬芬 | AG31: =VLOOKUP(G31,'指标体系-教育'!G:G,1,0)=G31 -> TRUE | AH31: 否 | AI31: =AI30 -> 业务拓展
A32: 营销 | B32: 强化业务拓展跟进 | D32: 业务拓展分析 | E32: 样机分析 | F32: 一级指标 | G32: 样机申请率 | H32: 样机申请量占额度比例 | I32: 样机申请量/样机额度 | J32: BG、分BU | K32: √ | L32: √ | N32: √ | O32: √ | P32: √ | Q32: √ | R32: √ | S32: √ | T32: √ | V32: √ | W32: % | X32: 日/周/月/季/年 | Y32: 两位小数点 | Z32: CRM/导入 | AA32: ★★★ | AB32: 内部管理 | AD32: 部门/BU负责人 | AF32: 龚芬芬 | AG32: 否 | AH32: 否 | AI32: =AI31 -> 业务拓展
A33: 营销 | B33: 强化业务拓展跟进 | D33: 业务拓展分析 | E33: 样机分析 | F33: 一级指标 | G33: 样机转销率 | H33: 样机转销量占申请比例 | I33: 样机转销量/样机申请量 | J33: BG、分BU | K33: √ | L33: √ | N33: √ | O33: √ | P33: √ | Q33: √ | R33: √ | S33: √ | T33: √ | V33: √ | W33: % | X33: 日/周/月/季/年 | Y33: 两位小数点 | Z33: CRM | AA33: ★★★ | AB33: 内部管理 | AD33: 部门/BU负责人 | AF33: 龚芬芬 | AG33: =VLOOKUP(G33,'指标体系-教育'!G:G,1,0)=G33 -> TRUE | AH33: 否 | AI33: =AI32 -> 业务拓展
A34: 营销 | B34: 强化业务拓展跟进 | D34: 业务拓展分析 | E34: 样机分析 | F34: 一级指标 | G34: 样机在外量 | H34: 样机未处理数量 | I34: 样机未处理数量 | J34: BG、分BU | K34: √ | L34: √ | N34: √ | O34: √ | P34: √ | Q34: √ | R34: √ | S34: √ | T34: √ | V34: √ | W34: 台 | X34: 日/周/月/季/年 | Y34: 无小数点 | Z34: CRM | AA34: ★★★ | AB34: 内部管理 | AD34: 部门/BU负责人 | AF34: 龚芬芬 | AG34: =VLOOKUP(G34,'指标体系-教育'!G:G,1,0)=G34 -> TRUE | AH34: 否 | AI34: =AI33 -> 业务拓展
A35: 营销 | B35: 强化业务拓展跟进 | D35: 业务拓展分析 | E35: 样机分析 | F35: 一级指标 | G35: 样机逾期率 | H35: 样机逾期量占在外量比例 | I35: 样机逾期量/样机在外量 | J35: BG、分BU | K35: √ | L35: √ | N35: √ | O35: √ | P35: √ | Q35: √ | R35: √ | S35: √ | T35: √ | V35: √ | W35: % | X35: 日/周/月/季/年 | Y35: 两位小数点 | Z35: CRM | AA35: ★★★ | AB35: 内部管理 | AD35: 部门/BU负责人 | AF35: 龚芬芬 | AG35: =VLOOKUP(G35,'指标体系-教育'!G:G,1,0)=G35 -> TRUE | AH35: 否 | AI35: =AI34 -> 业务拓展
A36: 营销 | B36: 强化业务拓展跟进 | D36: 业务拓展分析 | E36: 线索分析 | F36: 一级指标 | G36: 线索有效率 | H36: 有效线索数量占总线索数量比例 | I36: 有效线索量/总线索量 | J36: BG、分线上线下 | K36: √ | L36: √ | R36: √ | T36: √ | V36: √ | W36: % | X36: 日/周/月/季/年 | Y36: 两位小数点 | Z36: SCRM | AA36: ★★★ | AB36: 内部管理 | AD36: 部门/BU负责人 | AF36: 龚芬芬 | AG36: =VLOOKUP(G36,'指标体系-教育'!G:G,1,0)=G36 -> TRUE | AH36: 否 | AI36: =AI35 -> 业务拓展
A37: 营销 | B37: 强化业务拓展跟进 | D37: 业务拓展分析 | E37: 线索分析 | F37: 一级指标 | G37: 线索及时率 | H37: 及时处理线索数量占总线索数量比例 | I37: 及时线索量/总线索量 | J37: BG、分线上线下 | K37: √ | L37: √ | R37: √ | T37: √ | V37: √ | W37: % | X37: 日/周/月/季/年 | Y37: 两位小数点 | Z37: SCRM | AA37: ★★★ | AB37: 内部管理 | AD37: 部门/BU负责人 | AF37: 龚芬芬 | AG37: =VLOOKUP(G37,'指标体系-教育'!G:G,1,0)=G37 -> TRUE | AH37: 否 | AI37: =AI36 -> 业务拓展
A38: 营销 | B38: 强化业务拓展跟进 | D38: 业务拓展分析 | E38: 接单分析 | F38: 一级指标 | G38: 接单达成率 | H38: 完成接单目标的比例 | I38: 接单量/接单目标 | J38: BG、分BU | K38: √ | L38: √ | R38: √ | S38: √ | T38: √ | V38: √ | W38: % | X38: 日/周/月/季/年 | Y38: 两位小数点 | Z38: SCRM/CRM | AA38: ★★★ | AB38: 内部管理 | AD38: 部门/BU负责人 | AF38: 龚芬芬 | AG38: 否 | AH38: 否 | AI38: =AI37 -> 业务拓展
A39: 营销 | B39: 强化业务拓展跟进 | D39: 业务拓展分析 | E39: 签约分析 | F39: 二级指标 | G39: 签约达成率 | H39: 完成签约数量目标的比例 | I39: 签约数量/签约数量目标 | J39: 渠道平台、分区域、分办事处 | K39: √ | L39: √ | R39: √ | S39: √ | T39: √ | V39: √ | W39: % | X39: 日/周/月/季/年 | Y39: 两位小数点 | Z39: SCRM/导入 | AA39: ★★★ | AB39: 内部管理 | AD39: 区域/办事处负责人 | AF39: 龚芬芬 | AG39: =VLOOKUP(G39,'指标体系-教育'!G:G,1,0)=G39 -> TRUE | AI39: =AI38 -> 业务拓展
A40: 营销 | B40: 强化业务拓展跟进 | D40: 业务拓展分析 | E40: 商机分析 | F40: 二级指标 | G40: 商机达成率 | H40: 完成商机目标的比例 | I40: 商机额/商机目标 | J40: 1.渠道平台、分区域、分办事处 2.商机额=商机量*核心价，含税 | K40: √ | L40: √ | N40: √ | O40: √ | P40: √ | Q40: √ | R40: √ | S40: √ | T40: √ | V40: √ | W40: % | X40: 日/周/月/季/年 | Y40: 两位小数点 | Z40: SCRM/导入 | AA40: ★★★ | AB40: 内部管理 | AD40: 区域/办事处负责人 | AF40: 龚芬芬 | AG40: 否 | AI40: =AI39 -> 业务拓展
...

Sheet 指标体系-教育
B1: 一期 | C1: 部门价值填在此列 | AE1: 若无参考方法论可不填写
A2: 指标领域 | B2: 核心价值 | C2: 关键驱动因素 | D2: 分析主题域 | E2: 分析主题 | F2: 指标等级 | G2: 指标名称 | H2: 定义 | I2: 公式 | J2: 计算口径 | K2: 维度 | W2: 度量单位 | X2: 统计频率 | Y2: 统计精度 | Z2: 数据来源 | AA2: 优先级 | AB2: 指标用途 | AC2: 考核角色 | AD2: 要求角色 | AE2: 对应SCOR模型
K3: 期间 | L3: 事业部 | M3: 项目 | N3: 产品线 | O3: 产品型号 | P3: 系列 | Q3: 尺寸 | R3: 区域 | S3: 客户 | T3: 办事处 | U3: 仓位 | V3: 销售人员 | AF3: 对接人 | AG3: 是否相同 | AH3: 是否重复 | AI3: 核心价值
B4: 1.营收保障 | AE4: Reliability(可靠性)
A5: 营销 | B5: 扩大营业收入 | D5: 收入分析 | E5: 营业收入分析 | F5: 核心指标 | G5: 收入达成率 | H5: 完成收入预算、预测的比例 | I5: 营业收入/收入预算、预测 | J5: 1.BG 2、教务在闪畅收入 3.营业收入即不含税销售额 | K5: √ | L5: √ | M5: √ | N5: √ | O5: √ | P5: √ | Q5: √ | R5: √ | T5: √ | W5: % | X5: 日/周/月/季/年 | Y5: 一位小数点 | Z5: CRM/EDS/导入 | AA5: ★★★ | AB5: 内部管理 | AD5: 总裁/副总裁 | AF5: 陈亚婕 | AG5: =VLOOKUP(G5,'指标体系-企服'!G:G,1,0)=G5 -> TRUE | AI5: 营收保障
A6: 营销 | B6: 扩大营业收入 | D6: 收入分析 | E6: 营业收入分析 | F6: 核心指标 | G6: 收入同比增长率 | H6: 收入同比增长比例 | I6: 本期营业收入/同期营业收入 | J6: BG | K6: √ | L6: √ | N6: √ | O6: √ | P6: √ | Q6: √ | R6: √ | S6: √ | T6: √ | W6: % | X6: 月/季/年 | Y6: 一位小数点 | Z6: CRM/EDS | AA6: ★★★ | AB6: 内部管理 | AD6: 总裁/副总裁 | AF6: 陈亚婕 | AG6: =VLOOKUP(G6,'指标体系-企服'!G:G,1,0)=G6 -> TRUE | AH6: 否 | AI6: =AI5 -> 营收保障
A7: 营销 | B7: 扩大营业收入 | D7: 收入分析 | E7: 营业收入分析 | F7: 核心指标 | G7: 毛利率 | H7: 毛利额占收入比例 | I7: 毛利额/营业收入 | J7: BG | K7: √ | L7: √ | M7: √ | N7: √ | O7: √ | P7: √ | Q7: √ | R7: √ | S7: √ | T7: √ | W7: % | X7: 月/季/年 | Y7: 一位小数点 | Z7: CRM/EDS | AA7: ★★★ | AB7: 内部管理 | AD7: 总裁/副总裁 | AF7: 陈亚婕 | AG7: =VLOOKUP(G7,'指标体系-企服'!G:G,1,0)=G7 -> TRUE | AH7: 否 | AI7: =AI6 -> 营收保障
A8: 营销 | B8: 扩大营业收入 | D8: 收入分析 | E8: 营业收入分析 | F8: 一级指标 | G8: 营业收入 | H8: 营业收入 | I8: 营业收入 | J8: BG、分BU | K8: √ | L8: √ | M8: √ | N8: √ | O8: √ | P8: √ | Q8: √ | R8: √ | S8: √ | T8: √ | W8: 万元 | X8: 日/周/月/季/年 | Y8: 无小数点 | Z8: CRM/EDS | AA8: ★★★ | AB8: 内部管理 | AD8: 部门/BU负责人 | AF8: 陈亚婕 | AG8: =VLOOKUP(G8,'指标体系-企服'!G:G,1,0)=G8 -> TRUE | AH8: 否 | AI8: =AI7 -> 营收保障
A9: 营销 | B9: 扩大营业收入 | D9: 收入分析 | E9: 营业收入分析 | F9: 一级指标 | G9: 收入达成率及排名 | H9: 完成收入预算、预测的比例 | I9: 营业收入/收入预算、预测 | J9: BG、分BU | K9: √ | L9: √ | O9: √ | P9: √ | R9: √ | T9: √ | W9: % | X9: 日/周/月/季/年 | Y9: 一位小数点 | Z9: CRM/EDS/导入 | AA9: ★★★ | AB9: 内部管理 | AD9: 部门/BU负责人 | AF9: 陈亚婕 | AG9: =VLOOKUP(G9,'指标体系-企服'!G:G,1,0)=G9 -> TRUE | AH9: 否 | AI9: =AI8 -> 营收保障
A10: 营销 | B10: 扩大营业收入 | D10: 收入分析 | E10: 营业收入分析 | F10: 一级指标 | G10: 收入同比增长率 | H10: 收入同比增长比例 | I10: 本期营业收入/同期营业收入 | J10: BG、分BU | K10: √ | L10: √ | N10: √ | Q10: √ | R10: √ | S10: √ | T10: √ | W10: % | X10: 月/季/年 | Y10: 一位小数点 | Z10: CRM/EDS | AA10: ★★★ | AB10: 内部管理 | AD10: 部门/BU负责人 | AF10: 陈亚婕 | AG10: =VLOOKUP(G10,'指标体系-企服'!G:G,1,0)=G10 -> TRUE | AI10: =AI9 -> 营收保障
A11: 营销 | B11: 扩大营业收入 | D11: 收入分析 | E11: 销量分析 | F11: 一级指标 | G11: 整机销量 | H11: 整机销量 | I11: 整机销量 | J11: BG、分BU | K11: √ | L11: √ | M11: √ | N11: √ | O11: √ | P11: √ | Q11: √ | R11: √ | S11: √ | T11: √ | W11: 台 | X11: 日/周/月/季/年 | Y11: 无小数点 | Z11: CRM/EDS | AA11: ★★★ | AB11: 内部管理 | AD11: 部门/BU负责人 | AF11: 陈亚婕 | AG11: =VLOOKUP(G11,'指标体系-企服'!G:G,1,0)=G11 -> TRUE | AH11: 否 | AI11: =AI10 -> 营收保障
A12: 营销 | B12: 扩大营业收入 | D12: 收入分析 | E12: 销量分析 | F12: 一级指标 | G12: 整机销量同比增长率 | H12: 整机销量同比增长比例 | I12: 本期整机销量/同期整机销量 | J12: BG、分BU | K12: √ | L12: √ | N12: √ | O12: √ | P12: √ | Q12: √ | R12: √ | S12: √ | T12: √ | W12: % | X12: 月/季/年 | Y12: 一位小数点 | Z12: CRM/EDS | AA12: ★★★ | AB12: 内部管理 | AD12: 部门/BU负责人 | AF12: 陈亚婕 | AG12: =VLOOKUP(G12,'指标体系-企服'!G:G,1,0)=G12 -> TRUE | AH12: 否 | AI12: =AI11 -> 营收保障
A13: 营销 | B13: 扩大营业收入 | D13: 收入分析 | E13: 配比分析 | F13: 一级指标 | G13: 周边配比 | H13: 周边收入占整体(整机+周边)收入比例 | I13: 周边营业收入/整体营业收入 | J13: BG、分BU | K13: √ | L13: √ | N13: √ | O13: √ | P13: √ | Q13: √ | R13: √ | T13: √ | W13: % | X13: 月/季/年 | Y13: 一位小数点 | Z13: CRM/EDS | AA13: ★★ | AB13: 内部管理 | AD13: 部门/BU负责人 | AF13: 陈亚婕 | AG13: =VLOOKUP(G13,'指标体系-企服'!G:G,1,0)=G13 -> TRUE | AH13: 否 | AI13: =AI12 -> 营收保障
A14: 营销 | B14: 扩大营业收入 | D14: 收入分析 | E14: 配比分析 | F14: 一级指标 | G14: 主要周边销量配比 | H14: XX销量占对应整机销量比例 | I14: XX销量/对应整机销量 | J14: BG、分BU | K14: √ | L14: √ | N14: √ | O14: √ | P14: √ | Q14: √ | R14: √ | T14: √ | W14: % | X14: 月/季/年 | Y14: 一位小数点 | Z14: CRM/EDS | AA14: ★★ | AB14: 内部管理 | AD14: 部门/BU负责人 | AF14: 陈亚婕 | AG14: =VLOOKUP(G14,'指标体系-企服'!G:G,1,0)=G14 -> TRUE | AH14: 否 | AI14: =AI13 -> 营收保障
A15: 营销 | B15: 扩大营业收入 | D15: 收入分析 | E15: 价格分析 | F15: 一级指标 | G15: 低价量占比 | H15: 低价单销量占整机销量比例 | I15: 低价单整机销量/整机销量 | J15: 1.BG、分BU 2.低价：低于核心价 | K15: √ | L15: √ | N15: √ | O15: √ | R15: √ | S15: √ | T15: √ | V15: √ | W15: % | X15: 月/季/年 | Y15: 一位小数点 | Z15: CRM/EDS | AA15: ★★★ | AB15: 内部管理 | AD15: 部门/BU负责人 | AF15: 陈亚婕 | AG15: =VLOOKUP(G15,'指标体系-企服'!G:G,1,0)=G15 -> TRUE | AH15: 否 | AI15: =AI14 -> 营收保障
A16: 营销 | B16: 扩大营业收入 | D16: 收入分析 | E16: 价格分析 | F16: 一级指标 | G16: 低价金额占比 | H16: 低价单金额占全部金额比例 | I16: 低价单金额/全部营收 | J16: 1.BG、分BU 2.低价：低于核心价 | K16: √ | L16: √ | N16: √ | O16: √ | R16: √ | S16: √ | T16: √ | V16: √ | W16: % | X16: 月/季/年 | Y16: 一位小数点 | Z16: CRM/EDS | AA16: ★★★ | AB16: 内部管理 | AD16: 部门/BU负责人 | AF16: 陈亚婕 | AG16: 否 | AH16: 否 | AI16: =AI15 -> 营收保障
A17: 营销 | B17: 扩大营业收入 | D17: 收入分析 | E17: 价格分析 | F17: 一级指标 | G17: 平均单价 | H17: 产品平均单价 | I17: 营业收入/数量 | J17: 1.BG、分BU 2.低价：低于核心价 | K17: √ | L17: √ | M17: √ | N17: √ | O17: √ | P17: √ | Q17: √ | R17: √ | S17: √ | T17: √ | W17: % | X17: 月/季/年 | Y17: 一位小数点 | Z17: CRM/EDS | AA17: ★★★ | AB17: 内部管理 | AD17: 部门/BU负责人 | AF17: 陈亚婕 | AG17: 否 | AH17: 否 | AI17: =AI16 -> 营收保障
A18: 营销 | B18: 扩大营业收入 | D18: 收入分析 | E18: 订单分析 | F18: 一级指标 | G18: 订单平均金额 | H18: 平均每个订单的收入 | I18: 营业收入/订单数量 | J18: 1.BG、分BU、分区域、分办事处、分人员 2.销售额即IN-销售额，含税 | K18: √ | L18: √ | M18: √ | N18: √ | O18: √ | P18: √ | Q18: √ | R18: √ | S18: √ | T18: √ | W18: 万元 | X18: 日/周/月/季/年 | Y18: 无小数点 | Z18: CRM/EDS | AA18: ★★ | AB18: 内部管理 | AD18: 区域/办事处负责人 | AF18: 陈亚婕 | AG18: =VLOOKUP(G18,'指标体系-企服'!G:G,1,0)=G18 -> TRUE | AH18: 否 | AI18: =AI17 -> 营收保障
A19: 营销 | B19: 扩大营业收入 | D19: 收入分析 | E19: 营业收入分析 | F19: 二级指标 | G19: 营业收入 | H19: 营业收入 | I19: 营业收入 | J19: BG、分BU、分区域、分办事处、分人员 | K19: √ | L19: √ | M19: √ | N19: √ | O19: √ | P19: √ | Q19: √ | R19: √ | T19: √ | W19: 万元 | X19: 日/周/月/季/年 | Y19: 无小数点 | Z19: CRM/EDS | AA19: ★★★ | AB19: 内部管理 | AD19: 区域/办事处负责人 | AF19: 陈亚婕 | AG19: =VLOOKUP(G19,'指标体系-企服'!G:G,1,0)=G19 -> TRUE | AI19: =AI18 -> 营收保障
A20: 营销 | B20: 扩大营业收入 | D20: 收入分析 | E20: 营业收入分析 | F20: 二级指标 | G20: 收入达成率及排名 | H20: 完成收入目标的比例 | I20: 营业收入/收入目标 | J20: BG、分BU、分区域、分办事处、分人员 | K20: √ | L20: √ | N20: √ | O20: √ | P20: √ | Q20: √ | R20: √ | T20: √ | W20: % | X20: 日/周/月/季/年 | Y20: 一位小数点 | Z20: CRM/EDS/导入 | AA20: ★★★ | AB20: 内部管理 | AD20: 区域/办事处负责人 | AF20: 陈亚婕 | AG20: =VLOOKUP(G20,'指标体系-企服'!G:G,1,0)=G20 -> TRUE | AI20: =AI19 -> 营收保障
A21: 营销 | B21: 扩大营业收入 | D21: 收入分析 | E21: 营业收入分析 | F21: 二级指标 | G21: 收入同比增长率 | H21: 收入同比增长比例 | I21: 本期营业收入/同期营业收入 | J21: BG、分BU、分区域、分办事处、分人员 | K21: √ | L21: √ | N21: √ | O21: √ | P21: √ | Q21: √ | R21: √ | S21: √ | T21: √ | W21: % | X21: 月/季/年 | Y21: 一位小数点 | Z21: CRM/EDS | AA21: ★★★ | AB21: 内部管理 | AD21: 区域/办事处负责人 | AF21: 陈亚婕 | AG21: =VLOOKUP(G21,'指标体系-企服'!G:G,1,0)=G21 -> TRUE | AI21: =AI20 -> 营收保障
A22: 营销 | B22: 扩大营业收入 | D22: 收入分析 | E22: 销量分析 | F22: 二级指标 | G22: 整机销量 | H22: 整机销量 | I22: 整机销量 | J22: BG、分BU、分区域、分办事处、分人员 | K22: √ | L22: √ | M22: √ | N22: √ | O22: √ | P22: √ | Q22: √ | R22: √ | S22: √ | T22: √ | W22: 台 | X22: 日/周/月/季/年 | Y22: 无小数点 | Z22: CRM/EDS | AA22: ★★★ | AB22: 内部管理 | AD22: 区域/办事处负责人 | AF22: 陈亚婕 | AG22: =VLOOKUP(G22,'指标体系-企服'!G:G,1,0)=G22 -> TRUE | AI22: =AI21 -> 营收保障
A23: 营销 | B23: 扩大营业收入 | D23: 收入分析 | E23: 销量分析 | F23: 二级指标 | G23: 整机销量同比增长率 | H23: 整机销量同比增长比例 | I23: 本期整机销量/同期整机销量 | J23: BG、分BU、分区域、分办事处、分人员 | K23: √ | L23: √ | N23: √ | O23: √ | P23: √ | Q23: √ | R23: √ | S23: √ | T23: √ | W23: % | X23: 月/季/年 | Y23: 一位小数点 | Z23: CRM/EDS | AA23: ★★★ | AB23: 内部管理 | AD23: 区域/办事处负责人 | AF23: 陈亚婕 | AG23: =VLOOKUP(G23,'指标体系-企服'!G:G,1,0)=G23 -> TRUE | AI23: =AI22 -> 营收保障
A24: 营销 | B24: 扩大营业收入 | D24: 收入分析 | E24: 价格分析 | F24: 二级指标 | G24: 低价量占比 | H24: 低价单销量占整机销量比例 | I24: 低价单整机销量/整机销量 | J24: 1.BG、分BU、分区域、分办事处、分人员 2.低价：低于核心价 | K24: √ | L24: √ | N24: √ | O24: √ | R24: √ | S24: √ | T24: √ | V24: √ | W24: % | X24: 月/季/年 | Y24: 一位小数点 | Z24: CRM/EDS | AA24: ★★★ | AB24: 内部管理 | AD24: 区域/办事处负责人 | AF24: 陈亚婕 | AG24: =VLOOKUP(G24,'指标体系-企服'!G:G,1,0)=G24 -> TRUE | AI24: =AI23 -> 营收保障
A25: 营销 | B25: 扩大营业收入 | D25: 收入分析 | E25: 价格分析 | F25: 二级指标 | G25: 低价金额占比 | H25: 低价单金额占全部金额比例 | I25: 低价单金额/全部营收 | J25: 1.BG、分BU 2.低价：低于核心价 | K25: √ | L25: √ | N25: √ | O25: √ | R25: √ | S25: √ | T25: √ | V25: √ | W25: % | X25: 月/季/年 | Y25: 一位小数点 | Z25: CRM/EDS | AA25: ★★★ | AB25: 内部管理 | AD25: 部门/BU负责人 | AF25: 陈亚婕 | AG25: 否 | AI25: =AI24 -> 营收保障
A26: 营销 | B26: 扩大营业收入 | D26: 收入分析 | E26: 价格分析 | F26: 二级指标 | G26: 平均单价 | H26: 产品平均单价 | I26: 营业收入/数量 | J26: 1.BG、分BU 2.低价：低于核心价 | K26: √ | L26: √ | M26: √ | N26: √ | O26: √ | P26: √ | Q26: √ | R26: √ | S26: √ | T26: √ | W26: % | X26: 月/季/年 | Y26: 一位小数点 | Z26: CRM/EDS | AA26: ★★★ | AB26: 内部管理 | AD26: 部门/BU负责人 | AF26: 陈亚婕 | AG26: 否 | AI26: =AI25 -> 营收保障
A27: 营销 | B27: 扩大营业收入 | D27: 收入分析 | E27: 订单分析 | F27: 二级指标 | G27: 订单平均金额 | H27: 平均每个订单的收入 | I27: 营业收入/订单数量 | J27: 1.BG、分BU、分区域、分办事处、分人员 2.销售额即IN-销售额，含税 | K27: √ | L27: √ | M27: √ | N27: √ | O27: √ | P27: √ | Q27: √ | R27: √ | S27: √ | T27: √ | W27: 万元 | X27: 日/周/月/季/年 | Y27: 无小数点 | Z27: CRM/EDS | AA27: ★★ | AB27: 内部管理 | AD27: 区域/办事处负责人 | AF27: 陈亚婕 | AG27: =VLOOKUP(G27,'指标体系-企服'!G:G,1,0)=G27 -> TRUE | AI27: =AI26 -> 营收保障
B28: 2.业务拓展
A29: 营销 | B29: 强化业务拓展跟进 | D29: 业务拓展分析 | E29: 签约分析 | F29: 核心指标 | G29: 签约达成率 | H29: 完成签约数量目标的比例 | I29: 签约数量/签约数量目标 | J29: 教培事业部 | K29: √ | L29: √ | O29: √ | P29: √ | Q29: √ | R29: √ | S29: √ | T29: √ | W29: % | X29: 日/周/月/季/年 | Y29: 一位小数点 | Z29: SCRM/导入 | AA29: ★★ | AB29: 内部管理 | AD29: 总裁/副总裁 | AF29: 陈亚婕 | AG29: =VLOOKUP(G29,'指标体系-企服'!G:G,1,0)=G29 -> TRUE | AH29: 否 | AI29: 业务拓展
A30: 营销 | B30: 强化业务拓展跟进 | D30: 业务拓展分析 | E30: 商机分析 | F30: 核心指标 | G30: 商机项目数量/金额（分阶段） | H30: 商机项目数量/金额（分阶段） | J30: 1.BG 2.商机额销售额均不含税 | K30: √ | L30: √ | N30: √ | O30: √ | P30: √ | Q30: √ | R30: √ | S30: √ | T30: √ | V30: √ | W30: % | X30: 日/周/月/季/年 | Y30: 一位小数点 | Z30: SCRM | AA30: ★★★ | AB30: 内部管理 | AD30: 总裁/副总裁 | AF30: 陈亚婕 | AG30: 否 | AH30: 否 | AI30: =AI29 -> 业务拓展
A31: 营销 | B31: 强化业务拓展跟进 | D31: 业务拓展分析 | E31: 商机分析 | F31: 核心指标 | G31: 商机转化率 | H31: 线索转化为商机的比例 | I31: 线索中标量/金额 | J31: 1.营销平台 2.商机额销售额均含税 | K31: √ | L31: √ | N31: √ | O31: √ | P31: √ | Q31: √ | R31: √ | S31: √ | T31: √ | V31: √ | W31: % | X31: 日/周/月/季/年 | Y31: 一位小数点 | Z31: SCRM/CRM | AA31: ★★ | AB31: 内部管理 | AD31: 总裁/副总裁 | AF31: 陈亚婕 | AG31: =VLOOKUP(G31,'指标体系-企服'!G:G,1,0)=G31 -> TRUE | AH31: 否 | AI31: =AI30 -> 业务拓展
A32: 营销 | B32: 强化业务拓展跟进 | D32: 业务拓展分析 | E32: 商机分析 | F32: 核心指标 | G32: 商机转化率 | H32: 商机转化为订单的比例 | I32: 订单转化率金额 | J32: 1.营销平台 2.商机额销售额均含税 | K32: √ | L32: √ | N32: √ | O32: √ | P32: √ | Q32: √ | R32: √ | S32: √ | T32: √ | V32: √ | W32: % | X32: 日/周/月/季/年 | Y32: 一位小数点 | Z32: SCRM/CRM | AA32: ★★★ | AB32: 内部管理 | AD32: 总裁/副总裁 | AF32: 陈亚婕 | AG32: =VLOOKUP(G32,'指标体系-企服'!G:G,1,0)=G32 -> TRUE | AI32: =AI31 -> 业务拓展
A33: 营销 | B33: 强化业务拓展跟进 | D33: 业务拓展分析 | E33: 接单分析 | F33: 核心指标 | G33: 商机转化率 | H33: 订单转收入的比例 | I33: 收入转化率/金额 | J33: 1.营销平台 2.商机额销售额均含税 | K33: √ | L33: √ | N33: √ | R33: √ | S33: √ | T33: √ | V33: √ | W33: % | X33: 日/周/月/季/年 | Y33: 一位小数点 | Z33: SCRM/CRM | AA33: ★★★ | AB33: 内部管理 | AD33: 总裁/副总裁 | AF33: 陈亚婕 | AG33: =VLOOKUP(G33,'指标体系-企服'!G:G,1,0)=G33 -> TRUE | AI33: =AI32 -> 业务拓展
A34: 营销 | B34: 强化业务拓展跟进 | D34: 业务拓展分析 | E34: 接单分析 | F34: 核心指标 | G34: 接单收入 | H34: 订单数量/金额/单平均 | J34: BG、分BU | K34: √ | L34: √ | N34: √ | O34: √ | P34: √ | Q34: √ | R34: √ | S34: √ | T34: √ | V34: √ | W34: % | X34: 日/周/月/季/年 | Y34: 一位小数点 | Z34: SCRM/CRM | AA34: ★★★ | AB34: 内部管理 | AD34: 总裁/副总裁 | AF34: 陈亚婕 | AG34: 否 | AH34: 否 | AI34: =AI33 -> 业务拓展
A35: 营销 | B35: 强化业务拓展跟进 | D35: 业务拓展分析 | E35: 接单分析 | F35: 核心指标 | G35: 订单未出货 | H35: 订单未出货 | I35: 已接单未出货分时段 | J35: BG、分BU | K35: √ | L35: √ | N35: √ | O35: √ | P35: √ | Q35: √ | R35: √ | S35: √ | T35: √ | V35: √ | W35: % | X35: 日/周/月/季/年 | Y35: 一位小数点 | Z35: SCRM/CRM | AA35: ★★★ | AB35: 内部管理 | AD35: 总裁/副总裁 | AF35: 陈亚婕 | AG35: 否 | AH35: 否 | AI35: =AI34 -> 业务拓展
A36: 营销 | B36: 强化业务拓展跟进 | D36: 业务拓展分析 | E36: 接单分析 | F36: 核心指标 | G36: 合同配置效率 | J36: BG | K36: √ | L36: √ | N36: √ | R36: √ | S36: √ | T36: √ | W36: % | X36: 日/周/月/季/年 | Y36: 一位小数点 | Z36: SCRM/CRM | AA36: ★★ | AB36: 内部管理 | AD36: 总裁/副总裁 | AF36: 陈亚婕 | AG36: 否 | AH36: 否 | AI36: =AI35 -> 业务拓展
A37: 营销 | B37: 强化业务拓展跟进 | D37: 业务拓展分析 | E37: 签约分析 | F37: 一级指标 | G37: 签约达成率 | H37: 完成签约数量目标的比例 | I37: 签约数量/签约数量目标 | J37: 教培事业部 | K37: √ | L37: √ | R37: √ | S37: √ | T37: √ | W37: % | X37: 日/周/月/季/年 | Y37: 一位小数点 | Z37: SCRM/导入 | AA37: ★★ | AB37: 内部管理 | AD37: 部门/BU负责人 | AF37: 陈亚婕 | AG37: =VLOOKUP(G37,'指标体系-企服'!G:G,1,0)=G37 -> TRUE | AI37: =AI36 -> 业务拓展
A38: 营销 | B38: 强化业务拓展跟进 | D38: 业务拓展分析 | E38: 商机分析 | F38: 核心指标 | G38: 商机转化率 | H38: 线索转化为商机的比例 | I38: 线索中标量/金额 | J38: 1.营销平台 2.商机额销售额均含税 | K38: √ | L38: √ | N38: √ | O38: √ | P38: √ | Q38: √ | R38: √ | S38: √ | T38: √ | W38: % | X38: 日/周/月/季/年 | Y38: 一位小数点 | Z38: SCRM/CRM | AA38: ★★ | AB38: 内部管理 | AD38: 总裁/副总裁 | AF38: 陈亚婕 | AG38: =VLOOKUP(G38,'指标体系-企服'!G:G,1,0)=G38 -> TRUE | AI38: =AI37 -> 业务拓展
A39: 营销 | B39: 强化业务拓展跟进 | D39: 业务拓展分析 | E39: 商机分析 | F39: 核心指标 | G39: 商机转化率 | H39: 商机转化为订单的比例 | I39: 订单转化率金额 | J39: 1.营销平台 2.商机额销售额均含税 | K39: √ | L39: √ | N39: √ | O39: √ | P39: √ | Q39: √ | R39: √ | S39: √ | T39: √ | W39: % | X39: 日/周/月/季/年 | Y39: 一位小数点 | Z39: SCRM/CRM | AA39: ★★★ | AB39: 内部管理 | AD39: 总裁/副总裁 | AF39: 陈亚婕 | AG39: =VLOOKUP(G39,'指标体系-企服'!G:G,1,0)=G39 -> TRUE | AI39: =AI38 -> 业务拓展
A40: 营销 | B40: 强化业务拓展跟进 | D40: 业务拓展分析 | E40: 接单分析 | F40: 核心指标 | G40: 商机转化率 | H40: 订单转收入的比例 | I40: 收入转化率/金额 | J40: 1.营销平台 2.商机额销售额均含税 | K40: √ | L40: √ | N40: √ | R40: √ | S40: √ | T40: √ | V40: √ | W40: % | X40: 日/周/月/季/年 | Y40: 一位小数点 | Z40: SCRM/CRM | AA40: ★★★ | AB40: 内部管理 | AD40: 总裁/副总裁 | AF40: 陈亚婕 | AG40: =VLOOKUP(G40,'指标体系-企服'!G:G,1,0)=G40 -> TRUE | AI40: =AI39 -> 业务拓展
...

Sheet 指标体系
B1: 一期 | C1: 部门价值填在此列 | G1: =COUNTA(G3:G588) -> 159 | J1: 统一字段名称并校准 | K1: 在√格中直接补充字段名称和规则，如K5【年份】【月份】 | AH1: 若无参考方法论可不填写
A2: 指标领域 | B2: 核心价值 | C2: 关键驱动因素 | D2: 分析主题域 | E2: 分析主题 | F2: 指标等级 | G2: 指标名称 | H2: 定义 | I2: 公式 | J2: 计算口径 (含数据来源具体字段) | K2: 维度来源-字段名称 | Z2: 度量单位 | AA2: 统计频率 | AB2: 统计精度 | AC2: 数据来源 | AD2: 优先级 | AE2: 指标用途 | AF2: 考核角色 | AG2: 要求角色 | AH2: 对应SCOR模型 | AI2: 合并 | AJ2: 企服 | AK2: 教育 | AO2: 所属BG | AQ2: 上线时间
K3: 期间 | L3: 事业部 | M3: 项目 | N3: 产品型号 | O3: 产品线 | P3: 系列 | Q3: 尺寸 | R3: 区域 | S3: 办事处 | T3: 客户 | U3: 客户分类 | V3: 人员 | W3: 仓位 | X3: 库龄 | Y3: 用途 | AI3: 对接人 | AL3: 是否相同 | AM3: 是否重复 | AN3: 核心价值 | AO3: 教育 | AP3: 企服
B4: 1.营收保障 | AH4: Reliability(可靠性) | AO4: 是 | AP4: 是 | AQ4: 一期
A5: 营销 | B5: 扩大营业收入 | D5: 收入分析 | E5: 营业收入分析 | F5: 核心指标 | G5: 综合毛利率 | H5: 毛利额占收入比例 | I5: 综合毛利额/综合营业收入 | J5: 综合毛利额=综合营业收入-综合营业成本 1、综合营业收入 EDS系统中收入明细成本表， 筛选【冲销标记】不为 'Y'，【交易类型】 包含 ('',‘跨BG内部交易’)的数据，按【业绩所属事业部】列中事业部对应所属BG统计,汇总【订单行折扣后不含税金额】列; 2、综合营业成本 EDS系统中收入明细成本表，筛选【冲销标记】不为 'Y'，【交易类型】 包含 ('',‘跨BG内部交易’)的数据的数据，按【业绩所属事业部】列中事业部对应所属BG统计,汇总【原始合计成本】列 企业服务数据处理特殊规则 1、办事处： 北京办事处且【下单客户】包含“%天津%”，则调整到“天津办事处” 1、期间：【总账日期】+日期维 获取所对应的年\月\季 2、事业部：【产品所属事业部】 3、产品型号：【主销售型号】字段值 4、产品线：【产品型号】+产品型号维 ，获取对应的‘产品线分类’字段值 5、系列：【产品型号】+产品型号维，获取对应的‘产品系列’字段值 6、尺寸：产品型号】+产品型号维，获取对应的‘屏尺寸（英寸）’字段值 7、区域：【销售】+组织架构维，获取对应的区域值 8、办事处：【销售】+组织架构，获取对应的办事处 9、客户：【下单客户】 10、客户分类： 企业服务：【下单客户】+客户维，获取对应对应‘经销商类型’字段值 未来教育：【下单客户】+客户维，获取对应的‘客户分类’字段值 11、人员：【销售】 | K5: √ | L5: √ | N5: √ | O5: √ | P5: √ | Q5: √ | R5: √ | S5: √ | T5: √ | U5: √ | V5: √ | Z5: % | AA5: 月/季/年 | AB5: 两位小数点 | AC5: PBCS | AD5: ★★★ | AE5: 内部管理 | AI5: 潘敏君 | AJ5: 潘敏君 | AK5: 陈亚婕 | AL5: =VLOOKUP(G5,'指标体系-教育'!G:G,1,0)=G5 -> #N/A | AM5: 否 | AN5: 营收保障 | AO5: 是 | AP5: 是 | AQ5: 一期
A6: 营销 | B6: 扩大营业收入 | D6: 收入分析 | E6: 营业收入分析 | F6: 核心指标 | G6: BOM毛利率 | H6: 毛利额占收入比例 | I6: BOM毛利额/BOM营业收入 | J6: BOM毛利额=BOM营业收入-BOM营业成本 1、BOM营业收入 EDS系统中收入明细成本表 筛选【冲销标记】不为 'Y'，【交易类型】列 包含 ('',‘跨BG内部交易’)，【收入分类】=主营业务收入，【数据来源】不包含 (“FIN_ADJ","MAG_ADJ")，【物料编码】不包含"空"&"009"开头&"0"的数据，按【业绩所属事业部】列中事业部对应所属BG统计,汇总【订单行折扣后不含税金额】列; 2、BOM营业成本 EDS系统中收入明细成本表，筛选【冲销标记】不为 'Y'，【交易类型】 包含 ('',‘跨BG内部交易’)的数据，【收入分类】=主营业务收入，【数据来源】不包含 (“FIN_ADJ","MAG_ADJ")，【物料编码】不包含"空"&"009"开头&"0"的数据，，按【业绩所属事业部】列中事业部对应所属BG统计,汇总【原始合计成本】列 | K6: √ | L6: √ | N6: √ | O6: √ | P6: √ | Q6: √ | R6: √ | S6: √ | T6: √ | U6: √ | V6: √ | Z6: % | AA6: 月/季/年 | AB6: 两位小数点 | AC6: PBCS | AD6: ★★★ | AE6: 内部管理 | AI6: 潘敏君 | AJ6: 潘敏君 | AK6: 陈亚婕 | AL6: =VLOOKUP(G6,'指标体系-教育'!G:G,1,0)=G6 -> #N/A | AM6: 否 | AN6: 营收保障 | AP6: 是 | AQ6: 一期
A7: 营销 | B7: 扩大营业收入 | D7: 收入分析 | E7: 营业收入分析 | F7: 核心指标 | G7: 综合毛利率预算偏差率 | H7: 综合毛利率与预算综合毛利率之差 | I7: 综合毛利率 -预算综合毛利率 | J7: 综合毛利率预算偏差率=综合毛利率 -预算综合毛利率 1、综合毛利率：取上述综合毛利率 2、预算综合毛利率：手工导入 维度： 1、期间：收入成本表【年份】【月份】按月/季/年 2、事业部：按收入成本表上的【产品所属事业部】 | K7: √ | L7: √ | Z7: % | AA7: 月/季/年 | AB7: 两位小数点 | AC7: PBCS | AD7: ★★★ | AE7: 内部管理 | AI7: 潘敏君 | AJ7: 潘敏君 | AK7: 陈亚婕 | AL7: =VLOOKUP(G7,'指标体系-教育'!G:G,1,0)=G7 -> #N/A | AM7: 否 | AN7: 营收保障 | AP7: 是 | AQ7: 一期
A8: 营销 | B8: 扩大营业收入 | D8: 收入分析 | E8: 营业收入分析 | F8: 核心指标 | G8: BOM毛利率预算偏差率 | H8: BOM毛利率与预算BOM毛利率之差 | I8: BOM毛利率 -预算毛利率 | J8: BOM毛利率预算偏差率=BOM毛利率 -预算BOM毛利率 1、BOM毛利率：取上述BOM毛利率 2、预算BOM毛利率：手工导入 维度： 1、期间：收入成本表【年份】【月份】按月/季/年 2、事业部：按收入成本表上的【产品所属事业部】 | K8: √ | L8: √ | Z8: % | AA8: 月/季/年 | AB8: 两位小数点 | AC8: PBCS | AD8: ★★★ | AE8: 内部管理 | AI8: 潘敏君 | AJ8: 潘敏君 | AK8: 陈亚婕 | AL8: =VLOOKUP(G8,'指标体系-教育'!G:G,1,0)=G8 -> #N/A | AM8: 否 | AN8: 营收保障 | AP8: 是 | AQ8: 一期
B9: 扩大营业收入 | D9: 收入分析 | E9: 营业收入分析 | G9: 剔除返利后毛利率 | H9: 剔除供应商返利后的毛利率 | I9: （综合毛利额-返利额）/综合营业收入 | J9: 剔除返利后毛利额=综合营业收入-综合营业成本-返利额 1、综合营业收入 EDS系统中收入明细成本表， 筛选【冲销标记】不为 'Y'，【交易类型】 包含 ('',‘跨BG内部交易’)的数据，按【业绩所属事业部】列中事业部对应所属BG统计,汇总【订单行折扣后不含税金额】列; 2、综合营业成本 EDS系统中收入明细成本表，筛选【冲销标记】不为 'Y'，【交易类型】 包含 ('',‘跨BG内部交易’)的数据的数据，按【业绩所属事业部】列中事业部对应所属BG统计,汇总【原始合计成本】列 3、返利额 EDS系统中收入明细成本表，筛选【冲销标记】不为 'Y'，【交易类型】 包含 ('',‘跨BG内部交易’)的数据，【调整数备注】包含“返利”的数据，按【业绩所属事业部】列中事业部对应所属BG统计,汇总【原始合计成本】列 | AQ9: 一期
A10: 营销 | B10: 扩大营业收入 | D10: 收入分析 | E10: 营业收入分析 | F10: 一级指标 | G10: 综合营业收入 | H10: 综合营业收入 | I10: 综合营业收入 | J10: 1、综合营业收入 EDS系统中收入明细成本表，筛选【冲销标记】不为 'Y'，【交易类型】 包含 ('',‘跨BG内部交易’)的数据的数据，按【业绩所属事业部】列中事业部对应所属BG统计,汇总【订单行折扣后不含税金额】列; | K10: √ | L10: √ | N10: √ | O10: √ | P10: √ | Q10: √ | R10: √ | S10: √ | T10: √ | U10: √ | V10: √ | Z10: 万元 | AA10: 日/周/月/季/年 | AB10: 无小数点 | AC10: EDS | AD10: ★★★ | AE10: 内部管理 | AI10: 陈亚婕 | AJ10: 潘敏君 | AK10: 陈亚婕 | AL10: =VLOOKUP(G10,'指标体系-教育'!G:G,1,0)=G10 -> #N/A | AM10: 否 | AN10: =AN5 -> 营收保障 | AO10: 是 | AP10: 是 | AQ10: 一期
A11: 营销 | B11: 扩大营业收入 | D11: 收入分析 | E11: 营业收入分析 | F11: 一级指标 | G11: 销售目标完成率及排名 | H11: 完成销售目标的比例 | I11: 综合营业收入/销售目标 | J11: 销售目标完成率=综合营业收入/销售目标 1、综合营业收入 EDS系统中收入明细成本表，筛选【冲销标记】不为 'Y'，【交易类型】 包含 ('',‘跨BG内部交易’)的数据的数据，按【业绩所属事业部】列中事业部对应所属BG统计,汇总【订单行折扣后不含税金额】列; 2、销售目标：手工导入。 | Z11: % | AA11: 日/周/月/季/年 | AB11: 两位小数点 | AC11: EDS/导入 | AD11: ★★★ | AE11: 内部管理 | AI11: 陈亚婕 | AJ11: 潘敏君 | AK11: 陈亚婕 | AL11: 否 | AM11: 否 | AN11: =AN10 -> 营收保障 | AO11: 是 | AP11: 是 | AQ11: 一期
A12: 营销 | B12: 扩大营业收入 | D12: 收入分析 | E12: 营业收入分析 | F12: 一级指标 | G12: 预算完成率 | H12: 完成预算的比例 | I12: 综合营业收入/预算目标 | J12: 预算完成率=综合营业收入/预算目标 1、综合营业收入 EDS系统中收入明细成本表，筛选【冲销标记】不为 'Y'，【交易类型】 包含 ('',‘跨BG内部交易’)的数据的数据，按【业绩所属事业部】列中事业部对应所属BG统计,汇总【订单行折扣后不含税金额】列; 2、预算目标：手工导入。 | K12: √ | L12: √ | O12: √ | P12: √ | Q12: √ | R12: √ | S12: √ | Z12: % | AA12: 日/周/月/季/年 | AB12: 两位小数点 | AC12: EDS/导入 | AD12: ★★★ | AE12: 内部管理 | AI12: 陈亚婕 | AJ12: 潘敏君 | AK12: 陈亚婕 | AL12: 否 | AM12: 否 | AN12: =AN11 -> 营收保障 | AO12: 是 | AP12: 是 | AQ12: 一期
A13: 营销 | B13: 扩大营业收入 | D13: 收入分析 | E13: 营业收入分析 | F13: 一级指标 | G13: 预测完成率 | H13: 完成预测的比例 | I13: 综合营业收入/预测目标 | J13: 预测完成率=综合营业收入/预测目标 1、综合营业收入 EDS系统中收入明细成本表，筛选【冲销标记】不为 'Y'，【交易类型】 包含 ('',‘跨BG内部交易’)的数据的数据，按【业绩所属事业部】列中事业部对应所属BG统计,汇总【订单行折扣后不含税金额】列; 2、预测目标：手工导入。 | K13: √ | L13: √ | N13: √ | O13: √ | P13: √ | Q13: √ | R13: √ | S13: √ | Z13: % | AA13: 日/周/月/季/年 | AB13: 两位小数点 | AC13: EDS/导入 | AD13: ★★★ | AE13: 内部管理 | AI13: 陈亚婕 | AJ13: 潘敏君 | AK13: 陈亚婕 | AL13: 否 | AM13: 否 | AN13: =AN12 -> 营收保障 | AO13: 是 | AP13: 是 | AQ13: 一期
A14: 营销 | B14: 扩大营业收入 | D14: 收入分析 | E14: 营业收入分析 | F14: 一级指标 | G14: 收入同比增长率 | H14: 收入同比增长比例 | I14: （本期营业收入-同期收入）/同期营业收入 | J14: 收入同比增长率=（本期营业收入-同期收入）/同期营业收入 1、综合营业收入 EDS系统中收入明细成本表，筛选【冲销标记】不为 'Y'，【交易类型】 包含 ('',‘跨BG内部交易’)的数据的数据，按【业绩所属事业部】列中事业部对应所属BG统计,汇总【订单行折扣后不含税金额】列; | K14: √ | L14: √ | N14: √ | O14: √ | P14: √ | Q14: √ | R14: √ | S14: √ | Z14: % | AA14: 月/季/年 | AB14: 两位小数点 | AC14: EDS | AD14: ★★★ | AE14: 内部管理 | AI14: 陈亚婕 | AJ14: 潘敏君 | AK14: 陈亚婕 | AL14: =VLOOKUP(G14,'指标体系-教育'!G:G,1,0)=G14 -> TRUE | AM14: 否 | AN14: =AN11 -> 营收保障 | AO14: 是 | AP14: 是 | AQ14: 一期
A15: 营销 | B15: 扩大营业收入 | D15: 收入分析 | E15: 营业收入分析 | F15: 一级指标 | G15: 本年累计收入同比增长率 | H15: 本年累计收入同比增长比例 | I15: （本年累计营业收入-上年同期累计营业收入）/上年同期累计营业收入 | J15: 本年累计收入同比增长率=（本年累计营业收入-上年同期累计营业收入）/上年同期累计营业收入 1、综合营业收入 EDS系统中收入明细成本表，筛选【冲销标记】不为 'Y'，【交易类型】 包含 ('',‘跨BG内部交易’)的数据的数据，按【业绩所属事业部】列中事业部对应所属BG统计,汇总【订单行折扣后不含税金额】列; | K15: √ | L15: √ | N15: √ | O15: √ | P15: √ | Q15: √ | R15: √ | S15: √ | Z15: % | AA15: 月/季/年 | AB15: 两位小数点 | AC15: EDS | AD15: ★★★ | AE15: 内部管理 | AI15: 陈亚婕 | AJ15: 潘敏君 | AK15: 陈亚婕 | AL15: =VLOOKUP(G15,'指标体系-教育'!G:G,1,0)=G15 -> #N/A | AM15: 否 | AN15: =AN12 -> 营收保障 | AO15: 是 | AP15: 是 | AQ15: 一期
B16: 扩大营业收入 | D16: 收入分析 | E16: 营业收入分析 | G16: 新业务占比 | H16: 新业务收入占比 | I16: 新业务收入/综合营业收入 | J16: 新业务占比=新业务收入/综合营业收入 1、新业务收入 EDS系统中收入明细成本表，筛选【冲销标记】不为 'Y'，【交易类型】 包含 ('',‘跨BG内部交易’)的数据，【业绩所属事业部】所属BG为‘未来教育BG’且【业绩所属事业部】不包含‘多媒体事业部’的数据，汇总【订单行折扣后不含税金额】列; 2、综合营业收入 EDS系统中收入明细成本表，筛选【冲销标记】不为 'Y'，【交易类型】 包含 ('',‘跨BG内部交易’)的数据的数据，【业绩所属事业部】所属BG为‘未来教育BG’,汇总【订单行折扣后不含税金额】列; | K16: √ | L16: √ | R16: √ | S16: √ | AI16: 陈亚婕 | AL16: 否 | AM16: 否 | AN16: =AN12 -> 营收保障 | AO16: 是 | AQ16: 一期
B17: 扩大营业收入 | D17: 收入分析 | E17: 销量分析 | F17: 一级指标 | G17: 配比率 | H17: 周边产品占整机产品比 | I17: 周边产品数量/整机数量 | J17: 配比率=周边产品数量/整机数量 1、周边产品数量： EDS系统中收入明细成本表，【冲销标记】不为 'Y'，【交易类型】不含“教育BG内部交易”，【业绩所属事业部】所属BG为‘未来教育BG’，【产品线分类】为“音视频产品线”的数据，汇总【数量】列 2、整机数量： EDS系统中收入明细成本表，【冲销标记】不为 'Y'，【交易类型】不含“教育BG内部交易”，【业绩所属事业部】所属BG为‘未来教育BG’，【产品线分类】为“交互智能平板产品线”的数据，【物料小分类】为“智慧黑板”、“交互智能平板”，汇总【数量】列 维度： 区域、办事处、销售、物料小分类 学段：CRM 内销发货通知视睿全数据中的【学段】字段，通过【发货通知单号】映射到EDS收入成本明细表 | AI17: 郭梓樱 | AO17: 是
B18: 扩大营业收入 | D18: 收入分析 | E18: 销量分析 | F18: 一级指标 | G18: 数量占比 | H18: 数量占总数量比 | I18: 数量/总数量 | J18: 数量： EDS系统中收入明细成本表，【冲销标记】不为 'Y'，【交易类型】不含“教育BG内部交易”，【业绩所属事业部】所属BG为‘未来教育BG’，【产品线分类】筛选为“音视频产品线”，【数量】汇总 维度： 产品线、物料小分类 销售型号：EDS收入成本明细表，【销售型号】 大屏尺寸：①按【销售型号】汇总【合同号】；②用【合同号】汇总【尺寸】（包含【产品线分类】为“交互智能平板产品线”且【物料小分类】为“智慧黑板”、“交互智能平板”的【尺寸】）；③通过【合同号】建立【销售型号】和【尺寸】的对应关系。④若一个【合同号】中存在2个或者以上的【尺寸】，分摊比例为【物料小分类】为“智慧黑板”、“交互智能平板”的【数量】） 学段：CRM 内销发货通知视睿全数据中的【学段】字段，通过【发货通知单号】映射到EDS收入成本明细表 | AI18: 郭梓樱 | AO18: 是
B19: 扩大营业收入 | D19: 收入分析 | E19: 销量分析 | F19: 一级指标 | G19: 当月/当年交易渠道 | H19: 有交易记录的下单客户 | J19: 当月/当年交易渠道： EDS系统中收入明细成本表，【冲销标记】不为 'Y'，【交易类型】不含“教育BG内部交易”，【业绩所属事业部】所属BG为‘未来教育BG’，【下单客户】去重后的计数。 维度： 区域、办事处 | AI19: 郭梓樱
B20: 扩大营业收入 | D20: 收入分析 | E20: 销量分析 | F20: 一级指标 | G20: 当月/当年新增渠道 | H20: 新增的下单客户 | J20: 当月/当年交易渠道： EDS系统中收入明细成本表，【冲销标记】不为 'Y'，【交易类型】不含“教育BG内部交易”，【业绩所属事业部】所属BG为‘未来教育BG’，历史首次出现交易的【下单客户】去重后的计数。（需要考虑不同维度，存在对于办事处A是历史已经交易过的客户，但是对办事处B为首次） 维度： 区域、办事处 | AI20: 郭梓樱
B21: 扩大营业收入 | D21: 收入分析 | E21: 销量分析 | F21: 一级指标 | G21: 当月/当年新增渠道占比 | H21: 新增渠道占交易渠道比重 | I21: 新增渠道/交易渠道 | J21: 取值同上 | AI21: 郭梓樱
B22: 扩大营业收入 | D22: 收入分析 | E22: 销量分析 | F22: 一级指标 | G22: 当月/当年静默渠道 | H22: 过去1年无交易记录的客户 | J22: 当月/当年交易渠道： EDS系统中收入明细成本表，【冲销标记】不为 'Y'，【交易类型】不含“教育BG内部交易”，【业绩所属事业部】所属BG为‘未来教育BG’，当前日期距离【出货日期】超过1年（含1年）不存在交易记录的【下单客户】去重后的计数。 维度： 区域、办事处 | AI22: 郭梓樱
A23: 营销 | B23: 扩大营业收入 | D23: 收入分析 | E23: 销量分析 | F23: 一级指标 | G23: 整机销量 | H23: 整机销量 | I23: 整机销量 | J23: 1、整机销量 EDS系统中收入明细成本表，筛选【冲销标记】不为 'Y'，【交易类型】 包含 ('',‘跨BG内部交易’)的数据，产品型号+产品维 对应的商务产品标签类为‘整机’的数据，按【业绩所属事业部】中事业部对应所属BG统计,汇总【成套成品数量】列。增加：2020年3月的数据，【调整备注】为“本期未签收本期调减收入”的【成品数量】列须由正数改为对应的负数。 企服 成套成品数量换算规则： I产品型号+产品维 对应的商务产品标签类为‘整机’ ,则成套成品数量=数量；产品的小分类=‘LED工程屏’需按合同换算【成套成品数量】为1，一个合同号1台；ELSE 成套成品数量=成品数量 | K23: √ | L23: √ | N23: √ | O23: √ | P23: √ | Q23: √ | R23: √ | S23: √ | T23: √ | V23: √ | Z23: 台 | AA23: 日/周/月/季/年 | AB23: 无小数点 | AC23: EDS | AD23: ★★★ | AE23: 内部管理 | AI23: 陈亚婕 | AJ23: 潘敏君 | AK23: 陈亚婕 | AL23: =VLOOKUP(G23,'指标体系-教育'!G:G,1,0)=G23 -> TRUE | AM23: 否 | AN23: =AN14 -> 营收保障 | AO23: 是 | AP23: 是 | AQ23: 一期
A24: 营销 | B24: 扩大营业收入 | D24: 收入分析 | E24: 销量分析 | F24: 一级指标 | G24: 整机销量同比增长率 | H24: 整机销量同比增长比例 | I24: （本期整机销量-同期整机销量）/同期整机销量 | J24: 整机销量同比增长率=（本期整机销量-同期整机销量）/同期整机销量 1、整机销量 EDS系统中收入明细成本表，筛选【冲销标记】不为 'Y'，【交易类型】 包含 ('',‘跨BG内部交易’)的数据，产品型号+产品维 对应的商务产品标签类为‘整机’的数据，按【业绩所属事业部】列中事业部对应所属BG统计,汇总【成套成品数量】列。增加：2020年3月的数据，【调整备注】为“本期未签收本期调减收入”的【成品数量】列须由正数改为对应的负数。 产品的小分类=‘LED工程屏’需按合同换算【成套成品数量】为1，一个合同号1台 | Z24: % | AA24: 月/季/年 | AB24: 两位小数点 | AC24: EDS | AD24: ★★★ | AE24: 内部管理 | AI24: 陈亚婕 | AJ24: 潘敏君 | AK24: 陈亚婕 | AL24: =VLOOKUP(G24,'指标体系-教育'!G:G,1,0)=G24 -> TRUE | AM24: 否 | AN24: =AN23 -> 营收保障 | AO24: 是 | AP24: 是 | AQ24: 一期
A25: 营销 | B25: 扩大营业收入 | D25: 收入分析 | E25: 配比分析 | F25: 一级指标 | G25: 周边配比 | H25: 周边产品收入占整体(整机-会议平板+周边产品)收入比例 | I25: 周边产品营业收入/(会议平板+周边产品营业收入) | J25: 周边配比=周边产品营业收入/(整体营业收入) 教育 1、周边产品营业收入 EDS系统中收入明细成本表，筛选【冲销标记】不为 'Y'，【交易类型】 包含 ('',‘跨BG内部交易’)的数据，【业绩所属事业部】=‘多媒体事业部’AND 产品型号对应的产品线分类=‘音视频周边产品线’，汇总【订单行折扣后不含税金额】列; 2、整体收入 EDS系统中收入明细成本表，筛选【冲销标记】不为 'Y'，【交易类型】 包含 ('',‘跨BG内部交易’)的数据，【业绩所属事业部】=‘多媒体事业部’AND 产品型号对应的产品线分类 in (‘音视频周边产品线’,'智能平板产品线'），汇总【订单行折扣后不含税金额】列; 企服 1、周边产品营业收入 EDS系统中收入明细成本表，筛选【冲销标记】不为 'Y'，【交易类型】 包含 ('',‘跨BG内部交易’)的数据，产品型号+产品维对应的商务产品标签类为‘周边’+‘PC’的数据，按【业绩所属事业部】列中事业部对应所属BG统计，汇总【订单行折扣后不含税金额】列; 2、整体收入 EDS系统中收入明细成本表，筛选【冲销标记】不为 'Y'，【交易类型】 包含 ('',‘跨BG内部交易’)的数据，按【业绩所属事业部】列中事业部对应所属BG统计，汇总【订单行折扣后不含税金额】列; | K25: √ | L25: √ | Z25: % | AA25: 月/季/年 | AB25: 两位小数点 | AC25: PBCS | AD25: ★★ | AE25: 内部管理 | AI25: 潘敏君 | AJ25: 龚芬芬 | AK25: 陈亚婕 | AL25: =VLOOKUP(G25,'指标体系-教育'!G:G,1,0)=G25 -> TRUE | AM25: 否 | AN25: =AN24 -> 营收保障 | AO25: 是 | AP25: 是 | AQ25: 一期
A26: 营销 | B26: 扩大营业收入 | D26: 收入分析 | E26: 配比分析 | F26: 一级指标 | G26: 主要周边销量配比 | H26: XX销量占对应整机销量比例 | I26: XX销量/对应整机销量 | J26: @龚芬芬 暂无此配置表，主数据2期项目会包含此内容，实现时间后调【回复】ok 企服： XX型号销量：PBCS系统中收入成本表，筛选【产品所属事业部】中属于企业服务BG的事业部，筛选【冲销标记】不为 'Y'，剔除【交易类型】列为”XXBG内部交易“，汇总对应XX型号【数量】列 对应整机销量： 1、先根据提供的配置表，确定主要周边对应的整机型号，如SA06对应三代STU系列。 2、PBCS系统中收入成本表，筛选【产品所属事业部】中属于企业服务BG的事业部，筛选【冲销标记】不为 'Y'，剔除【交易类型】列为“跨BG内部交易“及”XXBG内部交易“，汇总对应整机【数量】列。 维度： 1、期间：收入成本表【年份】【月份】按月/季/年 2、事业部：按收入成本表上的【产品所属事业部】 教育： 1、周边销量配比=**销售型号销量/对应整机销量 周边产品定义： 【业绩所属事业部】=‘多媒体事业部’AND 产品型号对应的产品线分类=‘音视频周边产品线’ **销售型号销量： EDS系统中收入明细成本表，筛选【冲销标记】不为 'Y'，【交易类型】 包含 ('',‘跨BG内部交易’)的数据，【业绩所属事业部】=‘多媒体事业部’AND 产品型号对应的产品线分类=‘音视频周边产品线’，按销售型号汇总【数量】列; 对应整机销量 EDS系统中收入明细成本表，筛选【冲销标记】不为 'Y'，【交易类型】 包含 ('',‘跨BG内部交易’)的数据，【业绩所属事业部】=‘多媒体事业部’AND 产品型号对应的产品线分类 in (‘音视频周边产品线’,'智能平板产品线'），汇总【成套成品数量】列; | K26: √ | L26: √ | Z26: % | AA26: 月/季/年 | AB26: 两位小数点 | AC26: PBCS | AD26: ★★ | AE26: 内部管理 | AI26: 潘敏君 | AJ26: 龚芬芬 | AK26: 陈亚婕 | AL26: =VLOOKUP(G26,'指标体系-教育'!G:G,1,0)=G26 -> TRUE | AM26: 否 | AN26: =AN25 -> 营收保障 | AO26: 是 | AP26: 是 | AQ26: 一期
A27: 营销 | B27: 扩大营业收入 | D27: 收入分析 | E27: 订单分析 | F27: 一级指标 | G27: 订单平均金额 | H27: 平均每个订单含税销售额 | I27: 含税销售额/订单个数 | J27: 订单平均金额=含税销售额/订单个数 企业服务： 1、含税销售额 EDS系统中收入明细成本表，筛选【冲销标记】不为 'Y'，【交易类型】 包含 ('',‘跨BG内部交易’)的数据，【收入分类】为“主营业务收入”，且【合同号】不为空或NULL 的数据，按【业绩所属事业部】列中事业部对应所属BG统计，汇总【订单行折扣后不含税金额】*（1+【当月税率】） 2、订单个数 EDS系统中收入明细成本表，筛选，【冲销标记】不为 'Y'，【交易类型】 包含 ('',‘跨BG内部交易’)的数据，【收入分类】为“主营业务收入”且【合同号】不为空的数据，按【业绩所属事业部】列中事业部对应所属BG统计，汇总【合同号】个数，同一个合同号多行记录去重取1； 未来教育 1、含税销售额 EDS系统中收入明细成本表，筛选【冲销标记】不为 'Y'，【交易类型】 包含 ('',‘跨BG内部交易’)的数据，【合同号】不为空或NULL的数据，按【业绩所属事业部】列中事业部对应所属BG统计，汇总【订单行折扣后不含税金额】*（1+【当月税率】）； 2、订单个数 EDS系统中收入明细成本表，筛选，【冲销标记】不为 'Y'，【交易类型】 包含 ('',‘跨BG内部交易’)的数据，【合同号】不为空的数据，按【业绩所属事业部】列中事业部对应所属BG统计，汇总【合同号】个数，同一个合同号多行记录去重取1； | K27: √ | L27: √ | R27: √ | S27: √ | T27: √ | V27: √ | Z27: 万元 | AA27: 日/周/月/季/年 | AB27: 无小数点 | AC27: PBCS | AD27: ★★ | AE27: 内部管理 | AI27: 潘敏君 | AJ27: 龚芬芬 | AK27: 陈亚婕 | AL27: =VLOOKUP(G27,'指标体系-教育'!G:G,1,0)=G27 -> TRUE | AM27: 否 | AN27: =AN28 -> 营收保障 | AO27: 是 | AP27: 是 | AQ27: 一期
A28: 营销 | B28: 扩大营业收入 | D28: 收入分析 | E28: 价格分析 | F28: 一级指标 | G28: 低价销量占比 | H28: 低价单销量占整机销量比例 | I28: 低价整机销量/整机销量 | J28: 低价量占比=低价整机销量/整机销量 1、低价整机销量： 1）低价单 CRM系统-销售订单，订单行的底价字段值<单价字段值，则此订单编号+产品型号的行为低价订单行 2）低价单整机销量： EDS系统中收入明细成本表，筛选【冲销标记】不为 'Y'，【交易类型】 包含 ('',‘跨BG内部交易’)的数据，合同号对应的订单编号+产品型号为低价订单行，产品型号+产品维 对应的商务产品标签类为‘整机’的数据，按【业绩所属事业部】列中事业部对应所属BG统计,汇总【成套成品数量】列； 2020年3月的数据修改同上。 2、整机销量： EDS系统中收入明细成本表，筛选【冲销标记】不为 'Y'，【交易类型】 包含 ('',‘跨BG内部交易’)的数据，产品型号+产品维 对应的商务产品标签类为‘整机’的数据，按【业绩所属事业部】列中事业部对应所属BG统计,汇总【数量】列; | K28: √ | L28: √ | N28: √ | O28: √ | P28: √ | Q28: √ | R28: √ | S28: √ | T28: √ | V28: √ | Z28: % | AA28: 月/季/年 | AB28: 两位小数点 | AC28: CRM | AD28: ★★ | AE28: 内部管理 | AI28: 潘敏君 | AJ28: 龚芬芬 | AK28: 陈亚婕 | AL28: =VLOOKUP(G28,'指标体系-教育'!G:G,1,0)=G28 -> #N/A | AM28: 否 | AN28: =AN26 -> 营收保障 | AO28: 是 | AP28: 是 | AQ28: 一期
A29: 营销 | B29: 扩大营业收入 | D29: 收入分析 | E29: 价格分析 | F29: 一级指标 | G29: 低价营收占比 | H29: 低价单金额占全部金额比例 | I29: 低价营收/综合营业收入 | J29: 低价金额占比=低价单金额/全部营收 1、低价营收 CRM系统-销售订单，订单行的底价字段值<单价字段值，则此订单编号+产品型号的行为低价订单行 EDS系统中收入明细成本表，筛选【冲销标记】不为 'Y'，【交易类型】 包含 ('',‘跨BG内部交易’)的数据，合同号对应的订单编号+产品型号为低价订单行，按【业绩所属事业部】列中事业部对应所属BG统计,汇总【订单行折扣后不含税金额】列; 2、综合营业收入 EDS系统中收入明细成本表，筛选【冲销标记】不为 'Y'，【交易类型】 包含 ('',‘跨BG内部交易’)的数据的数据，按【业绩所属事业部】列中事业部对应所属BG统计,汇总【订单行折扣后不含税金额】列; | K29: √ | L29: √ | N29: √ | O29: √ | R29: √ | S29: √ | T29: √ | V29: √ | Z29: % | AA29: 月/季/年 | AB29: 一位小数点 | AC29: CRM/EDS | AD29: ★★★ | AE29: 内部管理 | AI29: 陈亚婕 | AK29: 陈亚婕 | AL29: 否 | AM29: 否 | AN29: =AN27 -> 营收保障 | AO29: 是 | AP29: 是 | AQ29: 一期
A30: 营销 | B30: 扩大营业收入 | D30: 收入分析 | E30: 价格分析 | F30: 一级指标 | G30: 平均单价 | H30: 产品平均单价 | I30: 综合营业收入/整机数量 | J30: 平均单价=综合营业收入/数量 1、综合营业收入 EDS系统中收入明细成本表，筛选【冲销标记】不为 'Y'，【交易类型】 包含 ('',‘跨BG内部交易’)的数据的数据，按【业绩所属事业部】列中事业部对应所属BG统计,汇总【订单行折扣后不含税金额】列; 2、数量 EDS系统中收入明细成本表，筛选【冲销标记】不为 'Y'，【交易类型】 包含 ('',‘跨BG内部交易’)的数据的数据，按【业绩所属事业部】列中事业部对应所属BG统计，汇总【成套成品数量】列。2020年3月数据修改同上。 产品的小分类=‘LED工程屏’需按合同换算【成套成品数量】为1，一个合同号1台 | K30: √ | L30: √ | N30: √ | O30: √ | P30: √ | Q30: √ | R30: √ | S30: √ | T30: √ | Z30: % | AA30: 月/季/年 | AB30: 一位小数点 | AC30: CRM/EDS | AD30: ★★★ | AE30: 内部管理 | AI30: 陈亚婕 | AK30: 陈亚婕 | AL30: 否 | AM30: 否 | AN30: =AN29 -> 营收保障 | AO30: 是 | AP30: 是 | AQ30: 一期
B31: 扩大营业收入 | D31: 收入分析 | E31: 价格分析 | G31: 预测出货量 | H31: 可在当天早上更新出当天出货数量 | I31: 预计出货数量 | J31: 1、出货整机数量 取CRM-发货通知单+门户发货通知，单据状态不包含‘已作废’,‘制单中’【发货日期】=当天，产品型号的商务标签=‘整机’的发货产品行，汇总 【数量】字段值 | AH31: 陈亚婕 | AJ31: 陈亚婕 | AK31: 否 | AL31: 否 | AM31: =AM30 -> 否 | AN31: 是 | AO31: 是 | AQ31: 一期
B32: 扩大营业收入 | D32: 收入分析 | E32: 价格分析 | G32: 预测出货收入 | H32: 可在当天早上更新出当天出货收入 | I32: 预计出货收入 | J32: 1、出货收入=销售额/(1+销售订单税率） 2、销售额=发货金额-返利额 取CRM-发货通知单+门户发货通知，单据状态不包含‘已作废’,‘制单中’【发货日期】=当天，汇总 【销售额】字段值 | AH32: 陈亚婕 | AJ32: 陈亚婕 | AK32: 否 | AL32: 否 | AM32: =AM31 -> 否 | AN32: 是 | AO32: 是 | AQ32: 一期
B33: 扩大营业收入 | D33: 收入分析 | E33: 价格分析 | G33: 预测出货收入 | H33: 可在当天早上更新出当天出货收入 | I33: 预计出货收入(含税) | J33: 1、出货收入含税=发货金额-返利额 取CRM-发货通知单+门户发货通知，单据状态不包含‘已作废’,‘制单中’【发货日期】=当天，汇总 【销售额】字段值 | AH33: 陈亚婕 | AJ33: 陈亚婕 | AK33: 否 | AL33: 否 | AM33: =AM32 -> 否 | AN33: 是 | AO33: 是 | AQ33: 一期
B34: 扩大营业收入 | D34: 收入分析 | E34: 价格分析 | G34: 区域管理营业收入 | H34: 区域管理营业收入 | I34: 区域管理营业收入=综合营业收入+门户发货通知已过账收入 | J34: BI另一套业务数据 只单独做区域-办事处营业收入 区域管理营业收入=综合营业收入+门户发货通知已过账收入 综合营业收入： EDS系统中收入明细成本表，筛选【冲销标记】不为 'Y'，【交易类型】 包含 ('',‘跨BG内部交易’)的数据的数据，按【业绩所属事业部】列中事业部对应所属BG统计,汇总【订单行折扣后不含税金额】列; 门户收入：经销商发货表，单据状态=‘已完成’，汇总【销售额】/(1+税率)字段值，日期：过帐时间，数量：地址数量，收入=(单价*数量）/(1+当月税率） EDS按照区域-办事处维度，区域取自字段【区域】，办事处取自字段【办事处】 维度： 1、期间：收入成本表【年份】【月份】按月/季/年 2、事业部：EDS部分按收入成本表上的【产品所属事业部】，门户取值【业绩归属事业部】 3、产品线：取收入成本表【销售型号】列，根据【销售型号】对应产品线匹配（详见产品目录） 4、按收入成本表中【销售型号】列，门户【销售型号】列 5、系列：取收入成本表【销售型号】列，根据【销售型号】对应系列匹配（详见产品目录） 6、尺寸：取收入成本表【销售型号】列，根据【销售型号】对应尺寸匹配（详见产品目录） 7、区域：按【销售人员】组织架构所在的区域，门户OUT销售所在部门 8、办事处：按【销售人员】组织架构所在的办事处，门户OUT销售所在部门 9、销售：eds取值【销售人员】+门户【 out销售】 （含事业部专岗销售，系统需要双重身份） | K34: √ | L34: √ | N34: √ | O34: √ | P34: √ | Q34: √ | R34: √ | S34: √ | T34: √ | U34: √ | V34: √ | Z34: % | AA34: 月/季/年 | AB34: 两位小数点 | AC34: PBCS | AD34: ★★★ | AE34: 内部管理 | AI34: 陈亚婕 | AQ34: 一期
B35: 扩大营业收入 | D35: 收入分析 | E35: 价格分析 | G35: 区域管理营业成本 | H35: 区域管理营业成本 | I35: 区域管理营业成本=综合营业成本+门户发货成本 | J35: BI另一套业务数据 只单独做区域-办事处营业收入 营业成本=综合营业成本+门户发货通知已过账收入对应追溯至EDS成本 综合营业成本： EDS系统中收入明细成本表，筛选【冲销标记】不为 'Y'，【交易类型】 包含 ('',‘跨BG内部交易’)的数据的数据，按【业绩所属事业部】列中事业部对应所属BG统计,汇总【原始合计成本】列 门户发货成本：经销商发货表中单据状态=‘已完成’，过帐时间不为空，发货成本=地址数量*原始单位成本 原始单位成本：收入成本明细表中下单客户=佳电（上海）管理有限公司，对应产品型号+生产批次+产品编码的【原始单位成本】 维度： 1、期间：收入成本表【年份】【月份】按月/季/年+经销商发货列表 过账时间 2、事业部：EDS部分按收入成本表上的【产品所属事业部】，门户取值【业绩归属事业部】 3、产品线：取收入成本表【销售型号】列，根据【销售型号】对应产品线匹配（详见产品目录） 4、按收入成本表中【销售型号】列，门户【销售型号】列 5、系列：取收入成本表【销售型号】列，根据【销售型号】对应系列匹配（详见产品目录） 6、尺寸：取收入成本表【销售型号】列，根据【销售型号】对应尺寸匹配（详见产品目录） 7、区域：按【销售人员】组织架构所在的区域，门户OUT销售所在部门 8、办事处：按【销售人员】组织架构所在的办事处，门户OUT销售所在部门 9、销售：eds取值【销售人员】+门户【 out销售】 （含事业部专岗销售，系统需要双重身份） | AQ35: 一期
B36: 扩大营业收入 | D36: 收入分析 | E36: 价格分析 | G36: 区域管理毛利率 | H36: 区域管理毛利率 | I36: 区域管理毛利率 | J36: (区域管理营业收入-区域管理营业成本)/区域管理营业成本 | AQ36: 一期
B37: 扩大营业收入 | D37: 收入分析 | E37: 低价分析 | G37: 低价幅度 | H37: 低价营收的低价幅度 | I37: 低价幅度=（底价销售收入-低价销售收入）/底价销售收入 | J37: 低价幅度=（底价销售收入-低价销售收入）/底价销售收入 1、底价销售收入 EDS系统中收入明细成本表，筛选【冲销标记】不为 'Y'，【交易类型】 包含 ('',‘跨BG内部交易’)的数据，合同号对应的订单编号+产品型号为低价订单行，汇总对应低价订单行的【底价】*【数量】/(1+当月税率) 2、低价销售收入 CRM系统-销售订单，订单行的底价字段值<单价字段值，则此订单编号+产品型号的行为低价订单行 EDS系统中收入明细成本表，筛选【冲销标记】不为 'Y'，【交易类型】 包含 ('',‘跨BG内部交易’)的数据，合同号对应的订单编号+产品型号为低价订单行，按【业绩所属事业部】列中事业部对应所属BG统计,汇总【订单行折扣后不含税金额】列; | K37: √ | L37: √ | N37: √ | O37: √ | P37: √ | Q37: √ | R37: √ | S37: √ | AJ37: 潘敏君 | AQ37: 一期
B38: 扩大营业收入 | D38: 收入分析 | E38: 销售个人业绩（本报表数据均取含税） | G38: 销售个人业绩（渠道、金融） | J38: 【需手工导入】 1、同期业绩（去年同期按月业绩）：需手工导入2019年1月-2020年8月的销售个人业绩数据 2、每月销售个人目标：从2020年Q4开始导入，预计9月底业务可提供数据导入。 销售个人业绩仅含SO业绩（本报表数据均取含税） SO业绩：CRM-销售管理-PSI报表管理-SZ PSI报表-销售OUT数据查询，期间按照【过账时间】，按照【OUT销售】字段统计【销售总金额】字段。 | AJ38: 车颖慧 | AQ38: 三期
B39: 扩大营业收入 | D39: 收入分析 | E39: 销售个人业绩（本报表数据均取含税） | G39: 销售个人业绩（除渠道、金融之外） | I39: =SI业绩+SO业绩 | J39: 【需手工导入】 1、同期业绩（去年同期按月业绩）：需手工导入2019年1月-2020年8月的销售个人业绩数据 2、每月销售个人目标：从2020年Q4开始导入，预计9月底业务可提供数据导入。 销售个人业绩=1、SI业绩+2、SO业绩（本报表数据均取含税） 1、SI业绩：CRM-内销发货通知查询，【业绩归属事业部】为视臻，选取【是否过账】为已过账，期间按照【过账日期】，按照【销售】字段统计【销售额】字段； 2、SO业绩：CRM-销售管理-PSI报表管理-SZ PSI报表-销售OUT数据查询，期间按照【过账时间】，按照【OUT销售】字段统计【销售总金额】字段。 | AJ39: 车颖慧 | AQ39: 三期
B40: 2.业务拓展
...

Sheet 事业部映射表（企服）
A1: 事业部 | B1: 核算事业部 | C1: 线上/线下
A2: 大客户平台 | B2: 大客户平台 | C2: 线下 | D2: 事业部映射关系关系为空，则默认为：线下
A3: CVTOUCH事业部 | B3: 电商事业部 | C3: 线上
A4: 电商部 | B4: 电商事业部 | C4: 线上
A5: 电商事业部 | B5: 电商事业部 | C5: 线上
A6: 会议ODM事业部 | B6: 渠道平台 | C6: 线下
A7: 会议事业部 | B7: 渠道平台 | C7: 线下
A8: 渠道平台 | B8: 渠道平台 | C8: 线下
A9: 金融事业部 | B9: 金融事业部 | C9: 线下
A10: 酒店地产事业部 | B10: 酒店地产事业部 | C10: 线下
A11: 军工事业部 | B11: 军工事业部 | C11: 线下
A12: 餐饮事业部 | B12: 新零售事业部 | C12: 线下
A13: 服装饰品事业部 | B13: 新零售事业部 | C13: 线下
A14: 家居建材事业部 | B14: 新零售事业部 | C14: 线下
... A25: 美业事业部 | B25: 新零售事业部 | C25: 线下

Sheet BI原型
A1: 目录页
C2: 营销
A3: 核心价值 | C3: 营收保障 | D3: 业务拓展 | E3: 运营效率提升 | I3: 客户提升 | K3: 组织能力提升
C4: 扩大营业收入 | D4: 强化业务拓展跟进 | E4: 扩大品牌认知 | F4: 提升市场运作效率 | G4: 严控费用 | H4: 提升运营效率 | I4: 提升经销商能力及效率 | J4: 优化客户结构 | K4: 提升营销人效 | L4: 增强团队能力建设
A7: 分析主题域 | C7: 收入分析 | D7: 业务拓展分析 | E7: 品牌分析 | F7: 市场分析 | G7: 费用分析 | H7: 运营效率分析 | I7: 经销商分析 | J7: 客户分析 | K7: 人效分析 | L7: 团队能力分析
A10: 分析主题 | C10: 营业收入分析 | D10: 签约分析 | E10: 品牌指数分析 | F10: 二级覆盖度 | G10: 招待费分析 | H10: 销售预测准确率分析 | I10: 渠道结构分析 | J10: 客户结构分析 | K10: 人员效率分析 | L10: 职级分析
C11: 销量分析 | D11: 商机分析 | E11: 专项曝光分析 | F11: 活动成效分析 | G11: 差旅费分析 | H11: 物流效率分析 | I11: 二级分析 | J11: 客户复购率分析
C12: 配比分析 | D12: 样机分析 | E12: 用户案例分析 | G12: 广宣费分析 | H12: 分仓效率分析 | I12: 返利分析 | J12: 客户流失分析(FML）
C13: 价格分析 | D13: 接单分析 | G13: 运输费分析 | H13: 库存周转分析 | I13: 库存分析 | J13: 定制项目投入产出分析
C14: 订单分析 | D14: 线索分析 | G14: 服务费分析 | I14: 赋能分析 | J14: 客户成单周期分析
J15: 订单分析价格
C16: 可点击跳转
A20: 分析页 | C20: 举例：营业收入分析
D21: 营业收入 | F21: 营业收入达成率 | G21: 排名 | I21: 营业收入同比
A22: 指标区
A24: 图表区
A26: （营业收入） | D26: 分BU | E26: 分办事处 | F26: 分人员 | G26: 分客户 | H26: 分产品

Sheet 日程安排
F1: 43891 | G1: 43892 | H1: 43893 | I1: 43894 | J1: 43895 | K1: 43896 | L1: 43897 | M1: 43898 | N1: 43899 | O1: 43900 | P1: 43901 | Q1: 43902 | R1: 43903 | S1: 43904 | T1: 43905 | U1: 43906 | V1: 43907 | W1: 43908 | X1: 43909 | Y1: 43910 | Z1: 43911 | AA1: 43912 | AB1: 43913 | AC1: 43914 | AD1: 43915 | AE1: 43916 | AF1: 43917 | AG1: 43918 | AH1: 43919 | AI1: 43920 | AJ1: 43921 | AK1: 43922 | AL1: 43923 | AM1: 43924 | AN1: 43925 | AO1: 43926 | AP1: 43927 | AQ1: 43928 | AR1: 43929 | AS1: 43930 | AT1: 43931 | AU1: 43932 | AV1: 43933 | AW1: 43934 | AX1: 43935 | AY1: 43936 | AZ1: 43937 | BA1: 43938 | BB1: 43939 | BC1: 43940 | BD1: 43941 | BE1: 43942 | BF1: 43943 | BG1: 43944 | BH1: 43945 | BI1: 43946 | BJ1: 43947 | BK1: 43948 | BL1: 43949 | BM1: 43950 | BN1: 43951
E2: 星期 | F2: 日 | G2: 一 | H2: 二 | I2: 三 | J2: 四 | K2: 五 | L2: 六 | M2: 日 | N2: 一 | O2: 二 | P2: 三 | Q2: 四 | R2: 五 | S2: 六 | T2: 日 | U2: 一 | V2: 二 | W2: 三 | X2: 四 | Y2: 五 | Z2: 六 | AA2: 日 | AB2: 一 | AC2: 二 | AD2: 三 | AE2: 四 | AF2: 五 | AG2: 六 | AH2: 日 | AI2: 一 | AJ2: 二 | AK2: 三 | AL2: 四 | AM2: 五 | AN2: 六 | AO2: 日 | AP2: 一 | AQ2: 二 | AR2: 三 | AS2: 四 | AT2: 五 | AU2: 六 | AV2: 日 | AW2: 一 | AX2: 二 | AY2: 三 | AZ2: 四 | BA2: 五 | BB2: 六 | BC2: 日 | BD2: 一 | BE2: 二 | BF2: 三 | BG2: 四 | BH2: 五 | BI2: 六 | BJ2: 日 | BK2: 一 | BL2: 二 | BM2: 三 | BN2: 四
A3: 序号 | B3: 项目 | C3: 责任部门 | D3: 跟进人 | E3: 进度 | F3: 3月 | AK3: 4月
F4: 1 | G4: 2 | H4: 3 | I4: 4 | J4: 5 | K4: 6 | L4: 7 | M4: 8 | N4: 9 | O4: 10 | P4: 11 | Q4: 12 | R4: 13 | S4: 14 | T4: 15 | U4: 16 | V4: 17 | W4: 18 | X4: 19 | Y4: 20 | Z4: 21 | AA4: 22 | AB4: 23 | AC4: 24 | AD4: 25 | AE4: 26 | AF4: 27 | AG4: 28 | AH4: 29 | AI4: 30 | AJ4: 31 | AK4: 1 | AL4: 2 | AM4: 3 | AN4: 4 | AO4: 5 | AP4: 6 | AQ4: 7 | AR4: 8 | AS4: 9 | AT4: 10 | AU4: 11 | AV4: 12 | AW4: 13 | AX4: 14 | AY4: 15 | AZ4: 16 | BA4: 17 | BB4: 18 | BC4: 19 | BD4: 20 | BE4: 21 | BF4: 22 | BG4: 23 | BH4: 24 | BI4: 25 | BJ4: 26 | BK4: 27 | BL4: 28 | BM4: 29 | BN4: 30
A5: 1 | B5: 梳理营销BI框架 | C5: 财务 | D5: 龚芬芬 | E5: 已完成
A6: =1+A5 -> 2 | B6: 会议：营销BI框架及指标沟通 | C6: =OFFSET($G$1,0,MATCH("★",$G6:$BO6,0)-1) -> 43893 | H6: ★
A7: =1+A6 -> 3 | B7: 梳理营销BI指标体系及优先级 | C7: 财务 | D7: 龚芬芬 | E7: 已完成
A8: =1+A7 -> 4 | B8: 整合企服教育指标，确定资源分配 | C8: IT | D8: 朱林生 | E8: 进行中
A9: =1+A8 -> 5 | B9: 会议：营销BI一期上线计划沟通 | C9: =OFFSET($G$1,0,MATCH("★",$G9:$BO9,0)-1) -> 43896 | K9: ★
A10: =1+A9 -> 6 | B10: 一期(★★★)上线准备 | C10: IT/财务 | D10: 袁红云 | E10: 未开始
A11: =1+A10 -> 7 | B11: 一期(★★)上线准备 | C11: IT/财务 | D11: 袁红云 | E11: 未开始
A12: =1+A11 -> 8 | B12: 一期(★)上线准备 | C12: IT/财务 | D12: 袁红云 | E12: 未开始
A13: =1+A12 -> 9 | B13: 营销BI一期上线及检验 | C13: IT/财务 | D13: 袁红云 | E13: 未开始
A14: =1+A13 -> 10 | B14: 会议：营销BI一期总结及二期上线沟通 | C14: =OFFSET($G$1,0,MATCH("★",$G14:$BO14,0)-1) -> 43927 | AP14: ★
A15: =1+A14 -> 11 | B15: 二期(★★★)上线准备 | C15: IT/财务 | D15: 袁红云 | E15: 未开始
A16: =1+A15 -> 12 | B16: 二期(★★)上线准备 | C16: IT/财务 | D16: 袁红云 | E16: 未开始
A17: =1+A16 -> 13 | B17: 二期(★)上线准备 | C17: IT/财务 | D17: 袁红云 | E17: 未开始
A18: =1+A17 -> 14 | B18: 营销BI二期上线及检验 | C18: IT/财务 | D18: 袁红云 | E18: 未开始
A19: =1+A18 -> 15 | B19: 会议：营销BI总结 | C19: =OFFSET($G$1,0,MATCH("★",$G19:$BO19,0)-1) -> 43951 | BN19: ★
K22: 节假日 | N22: 工作开展日 | R22: 阶段工作结束日 | V22: ★ | W22: 会议

Sheet 会议
A1: 会议时间 | B1: 会议主题 | C1: 与会人 | D1: 会议纪要 | E1: 附表 | F1: 负责人 | G1: 完成时间
